<mujoco model="allegro">
  <compiler angle="radian"/>
  <default>
    <joint damping="10"/>
    <muscle ctrllimited="true" ctrlrange="0 100"/>
    <motor ctrllimited="true" ctrlrange="-3 3" gear="1"/>
    <general ctrllimited="true"/>
   </default>

    <!-- <default>
        <joint damping="10"/>
        <muscle ctrllimited="true" ctrlrange="0 100"/>
        <motor ctrllimited="true" ctrlrange="-3 3" gear="1"/>
        <position ctrllimited="true" kp="10"/>
    </default> -->
    <contact>
        <exclude body1="allegro_hand" body2="link_l12.0"/>
        <exclude body1="allegro_hand" body2="link_l0.0"/>
        <exclude body1="allegro_hand" body2="link_l4.0"/>
        <exclude body1="allegro_hand" body2="link_l8.0"/>
    </contact>



  <asset>
    <mesh name="base_link_left" file="allegro/meshes/base_link_left.STL"/>
    <mesh name="link_0.0" file="allegro/meshes/link_0.0.obj"/>
    <mesh name="link_1.0" file="allegro/meshes/link_1.0.obj"/>
    <mesh name="link_2.0" file="allegro/meshes/link_2.0.obj"/>
    <mesh name="link_3.0" file="allegro/meshes/link_3.0.obj"/>
    <mesh name="link_12.0_left" file="allegro/meshes/link_12.0_left.obj"/>
    <mesh name="link_13.0" file="allegro/meshes/link_13.0.obj"/>
    <mesh name="link_14.0" file="allegro/meshes/link_14.0.obj"/>
    <mesh name="link_15.0" file="allegro/meshes/link_15.0.obj"/>
    <mesh name="digit2_sensor_base" file="allegro/meshes/digit2_sensor_base.obj"/>
    <mesh name="digit2_sensor_base_tip" file="allegro/meshes/digit2_sensor_base_tip.obj"/>
    <mesh name="camera_mount" file="allegro/meshes/left_mount_camobj.obj"/>
    <mesh name="zed_x" file="allegro/meshes/zed_x.obj"/>
  </asset>

  <worldbody>
    <!-- <geom name="ik_target_sphere" pos="0 0 0" type="sphere" size="0.15" rgba="1 0 0 0.8" contype="0" conaffinity="0" group="2"/> -->
    <body name="allegro_hand" pos="0 0 0" quat=" 0 0 -0.3826834 0.9238795" >
    <geom type="mesh" contype="0" conaffinity="0" group="1" density="0" rgba="0.2 0.2 0.2 1" pos="0.0 0 -0.001" mesh="camera_mount" size="0.1 1 1"/>
        <!-- <body name="ik_target_visual" pos="0 0 0"> -->
            <!-- <geom name="ik_target_sphere" type="sphere" size="0.15" rgba="1 0 0 0.8" contype="0" conaffinity="0" group="2"/> -->
        <!-- </body> -->
        <site name="ft_frame" pos="0 0 0" size="0.01 0.01 0.01" rgba="1 0 0 1" type="sphere" group="1" />
            <geom type="mesh" contype="0" conaffinity="0" group="1" density="0" rgba="0.2 0.2 0.2 1" pos="-0.050 -0.14 -0.04" quat="0.467500309  0.19985314194  -0.69700309  0.19985314194" mesh="zed_x" size="0.0001 0.0001 0.0001"/>
                <!-- <camera name="right_eye_in_hand" pos="-0.0296 0.12 -0.052" quat="0.467500309  -0.19985314194  -0.69700309  -0.19985314194" fovy="80" resolution="480 300"/> -->
            <camera name="right_eye_in_hand" pos="-0.0212 -0.105 -0.042" quat="0.5267500309  0.19985314194  -0.69700309  0.19985314194" fovy="78" resolution="480 300"/>


            <!-- This site was added for visualization. -->
        <body name="eef" pos="0 0 0.145" quat="1 0 0 0">
            <site name="grip_site" pos="0 0 0" size="0.01 0.01 0.01" rgba="1 0 0 0.5" type="sphere" group="1"/>
            <site name="ee_x" pos="0.1 0 0" size="0.005 .1"  quat="1 1 0 0 " rgba="1 0 0 0" type="cylinder" group="1"/>
            <site name="ee_y" pos="0 0.1 0" size="0.005 .1" quat="1 0 0 0" rgba="0 1 0 0" type="cylinder" group="1"/>
            <site name="ee_z" pos="0 0 0.1" size="0.005 .1" quat="1 0 0 0" rgba="0 0 1 0" type="cylinder" group="1"/>
            <!-- This site was added for visualization. -->
            <site name="grip_site_cylinder" pos="0 0 0" size="0.005 10" rgba="0 1 0 0.3" type="cylinder" group="1"/>
        </body>
        <geom quat="0.707388 -0.706825 0 0" type="mesh" contype="0" conaffinity="0" group="1" density="0" rgba="0.2 0.2 0.2 1" mesh="base_link_left"/>
        <geom size="0.0204 0.03 0.0275" pos="-0.0093 0 -0.0475" quat="0.707388 -0.706825 0 0" type="box" rgba="0.2 0.2 0.2 1"/>
        <body name="link_l0.0" pos="0 0.0435 -0.001542" quat="0.999048 -0.0436194 0 0">
            <inertial pos="0 0 0" quat="0.707107 0.707107 0 0" mass="0.0119" diaginertia="1.01667e-06 1.01667e-06 6.47677e-07"/>
            <joint name="joint_l_0.0" pos="0 0 0" axis="0 0 1" range="-0.47 0.47" damping="1.0" actuatorfrcrange="-0.35 0.35" frictionloss="0.2"/>
            <geom type="mesh" contype="0" conaffinity="0" group="1" density="0" rgba="0.2 0.2 0.2 1" mesh="link_0.0"/>
            <geom size="0.0098 0.01375 0.0082" pos="0 0 0.0082" type="box" rgba="0.2 0.2 0.2 1"/>
            <body name="link_l1.0" pos="0 0 0.0164">
                <inertial pos="0 0 0" quat="0.702596 0.559386 -0.178354 0.402039" mass="0.065" diaginertia="6.12799e-05 6.12799e-05 6.12799e-05"/>
                <joint name="joint_l_1.0" pos="0 0 0" axis="0 1 0" range="-0.196 1.61" damping="1.0" actuatorfrcrange="-0.35 0.35" frictionloss="0.2"/>
                <geom type="mesh" contype="0" conaffinity="0" group="1" density="0" rgba="0.2 0.2 0.2 1" mesh="link_1.0"/>
                <geom size="0.0098 0.01375 0.027" pos="0 0 0.027" type="box" rgba="0.2 0.2 0.2 1"/>
                <body name="link_l2.0" pos="0 0 0.054">
                    <inertial pos="0 0 0" quat="0.719796 0.528175 -0.157463 0.422055" mass="0.0355" diaginertia="2.20969e-05 2.20969e-05 2.20969e-05"/>
                    <joint name="joint_l_2.0" pos="0 0 0" axis="0 1 0" range="-0.174 1.709" damping="1.0" actuatorfrcrange="-0.35 0.35" frictionloss="0.2"/>
                    <geom type="mesh" contype="0" conaffinity="0" group="1" density="0" rgba="0.2 0.2 0.2 1" mesh="link_2.0"/>
                    <geom size="0.0098 0.01375 0.0192" pos="0 0 0.0192" type="box" rgba="0.2 0.2 0.2 1"/>
                    <body name="link_l3.0" pos="0 0 0.0384">
                        <inertial pos="0 0 0.0135135" mass="0.0296" diaginertia="8.8812e-06 8.8812e-06 6.2866e-06"/>
                        <joint name="joint_l_3.0" pos="0 0 0" axis="0 1 0" range="-0.227 1.618" damping="1.0" actuatorfrcrange="-0.35 0.35" frictionloss="0.2"/>
                        <geom type="mesh" contype="0" conaffinity="0" group="1" density="0" rgba="0.2 0.2 0.2 1" mesh="link_3.0"/>
                        <geom size="0.0098 0.01175 0.007" pos="0 0 0.008" type="box" rgba="0.2 0.2 0.2 1"/>
                        <geom pos="0 0 0.02" quat="1 0 0 0" type="mesh" contype="0" conaffinity="0" group="1" density="0" rgba="0.9 0.9 0.9 1" mesh="digit2_sensor_base"/>
                        <geom pos="0 0 0.02" quat="1 0 0 0" type="mesh" rgba="0.9 0.9 0.9 1" mesh="digit2_sensor_base"/>
                        <geom pos="0 0 0.02" type="mesh" contype="0" conaffinity="0" group="1" density="0" rgba="0.9 0.9 0.9 1" mesh="digit2_sensor_base_tip"/>
                        <geom pos="0 0 0.02" type="mesh" rgba="0.9 0.9 0.9 1" mesh="digit2_sensor_base_tip"/>
                    </body>
                </body>
            </body>
        </body>
        <body name="link_l4.0" pos="0 0 0.0007">
            <inertial pos="0 0 0" quat="0.707107 0.707107 0 0" mass="0.0119" diaginertia="1.01667e-06 1.01667e-06 6.47677e-07"/>
            <joint name="joint_l_4.0" pos="0 0 0" axis="0 0 1" range="-0.47 0.47" damping="1.0" actuatorfrcrange="-0.35 0.35" frictionloss="0.2"/>
            <geom type="mesh" contype="0" conaffinity="0" group="1" density="0" rgba="0.2 0.2 0.2 1" mesh="link_0.0"/>
            <geom size="0.0098 0.01375 0.0082" pos="0 0 0.0082" type="box" rgba="0.2 0.2 0.2 1"/>
            <body name="link_l5.0" pos="0 0 0.0164">
                <inertial pos="0 0 0" quat="0.702596 0.559386 -0.178354 0.402039" mass="0.065" diaginertia="6.12799e-05 6.12799e-05 6.12799e-05"/>
                <joint name="joint_l_5.0" pos="0 0 0" axis="0 1 0" range="-0.196 1.61" damping="1.0" actuatorfrcrange="-0.35 0.35" frictionloss="0.2"/>
                <geom type="mesh" contype="0" conaffinity="0" group="1" density="0" rgba="0.2 0.2 0.2 1" mesh="link_1.0"/>
                <geom size="0.0098 0.01375 0.027" pos="0 0 0.027" type="box" rgba="0.2 0.2 0.2 1"/>
                <body name="link_l6.0" pos="0 0 0.054">
                    <inertial pos="0 0 0" quat="0.719796 0.528175 -0.157463 0.422055" mass="0.0355" diaginertia="2.20969e-05 2.20969e-05 2.20969e-05"/>
                    <joint name="joint_l_6.0" pos="0 0 0" axis="0 1 0" range="-0.174 1.709" damping="1.0" actuatorfrcrange="-0.35 0.35" frictionloss="0.2"/>
                    <geom type="mesh" contype="0" conaffinity="0" group="1" density="0" rgba="0.2 0.2 0.2 1" mesh="link_2.0"/>
                    <geom size="0.0098 0.01375 0.0192" pos="0 0 0.0192" type="box" rgba="0.2 0.2 0.2 1"/>
                    <body name="link_l7.0" pos="0 0 0.0384">
                        <inertial pos="0 0 0.0135135" mass="0.0296" diaginertia="8.8812e-06 8.8812e-06 6.2866e-06"/>
                        <joint name="joint_l_7.0" pos="0 0 0" axis="0 1 0" range="-0.227 1.618" damping="1.0" actuatorfrcrange="-0.35 0.35" frictionloss="0.2"/>
                        <geom type="mesh" contype="0" conaffinity="0" group="1" density="0" rgba="0.2 0.2 0.2 1" mesh="link_3.0"/>
                        <geom size="0.0098 0.01175 0.007" pos="0 0 0.008" type="box" rgba="0.2 0.2 0.2 1"/>
                        <geom pos="0 0 0.02" quat="1 0 0 0" type="mesh" contype="0" conaffinity="0" group="1" density="0" rgba="0.9 0.9 0.9 1" mesh="digit2_sensor_base"/>
                        <geom pos="0 0 0.02" quat="1 0 0 0" type="mesh" rgba="0.9 0.9 0.9 1" mesh="digit2_sensor_base"/>
                        <geom pos="0 0 0.02" type="mesh" contype="0" conaffinity="0" group="1" density="0" rgba="0.9 0.9 0.9 1" mesh="digit2_sensor_base_tip"/>
                        <geom pos="0 0 0.02" type="mesh" rgba="0.9 0.9 0.9 1" mesh="digit2_sensor_base_tip"/>
                    </body>
                </body>
            </body>
        </body>
        <body name="link_l8.0" pos="0 -0.0435 -0.001542" quat="0.999048 0.0436194 0 0">
            <inertial pos="0 0 0" quat="0.707107 0.707107 0 0" mass="0.0119" diaginertia="1.01667e-06 1.01667e-06 6.47677e-07"/>
            <joint name="joint_l_8.0" pos="0 0 0" axis="0 0 1" range="-0.47 0.47" damping="1.0" actuatorfrcrange="-0.35 0.35" frictionloss="0.2"/>
            <geom type="mesh" contype="0" conaffinity="0" group="1" density="0" rgba="0.2 0.2 0.2 1" mesh="link_0.0"/>
            <geom size="0.0098 0.01375 0.0082" pos="0 0 0.0082" type="box" rgba="0.2 0.2 0.2 1"/>
            <body name="link_l9.0" pos="0 0 0.0164">
                <inertial pos="0 0 0" quat="0.702596 0.559386 -0.178354 0.402039" mass="0.065" diaginertia="6.12799e-05 6.12799e-05 6.12799e-05"/>
                <joint name="joint_l_9.0" pos="0 0 0" axis="0 1 0" range="-0.196 1.61" damping="1.0" actuatorfrcrange="-0.35 0.35" frictionloss="0.2"/>
                <geom type="mesh" contype="0" conaffinity="0" group="1" density="0" rgba="0.2 0.2 0.2 1" mesh="link_1.0"/>
                <geom size="0.0098 0.01375 0.027" pos="0 0 0.027" type="box" rgba="0.2 0.2 0.2 1"/>
                <body name="link_l10.0" pos="0 0 0.054">
                    <inertial pos="0 0 0" quat="0.719796 0.528175 -0.157463 0.422055" mass="0.0355" diaginertia="2.20969e-05 2.20969e-05 2.20969e-05"/>
                    <joint name="joint_l_10.0" pos="0 0 0" axis="0 1 0" range="-0.174 1.709" damping="1.0" actuatorfrcrange="-0.35 0.35" frictionloss="0.2"/>
                    <geom type="mesh" contype="0" conaffinity="0" group="1" density="0" rgba="0.2 0.2 0.2 1" mesh="link_2.0"/>
                    <geom size="0.0098 0.01375 0.0192" pos="0 0 0.0192" type="box" rgba="0.2 0.2 0.2 1"/>
                    <body name="link_l11.0" pos="0 0 0.0384">
                        <inertial pos="0 0 0.0135135" mass="0.0296" diaginertia="8.8812e-06 8.8812e-06 6.2866e-06"/>
                        <joint name="joint_l_11.0" pos="0 0 0" axis="0 1 0" range="-0.227 1.618" damping="1.0" actuatorfrcrange="-0.35 0.35" frictionloss="0.2"/>
                        <geom type="mesh" contype="0" conaffinity="0" group="1" density="0" rgba="0.2 0.2 0.2 1" mesh="link_3.0"/>
                        <geom size="0.0098 0.01175 0.007" pos="0 0 0.008" type="box" rgba="0.2 0.2 0.2 1"/>
                        <geom pos="0 0 0.02" quat="1 0 0 0" type="mesh" contype="0" conaffinity="0" group="1" density="0" rgba="0.9 0.9 0.9 1" mesh="digit2_sensor_base"/>
                        <geom pos="0 0 0.02" quat="1 0 0 0" type="mesh" rgba="0.9 0.9 0.9 1" mesh="digit2_sensor_base"/>
                        <geom pos="0 0 0.02" type="mesh" contype="0" conaffinity="0" group="1" density="0" rgba="0.9 0.9 0.9 1" mesh="digit2_sensor_base_tip"/>
                        <geom pos="0 0 0.02" type="mesh" rgba="0.9 0.9 0.9 1" mesh="digit2_sensor_base_tip"/>
                    </body>
                </body>
            </body>
        </body>
        <body name="link_l12.0" pos="-0.0182 -0.019333 -0.045987" quat="0.477714 0.521334 -0.521334 0.477714">
            <inertial pos="0 0 0" quat="0.692635 0.569362 -0.07143 0.437013" mass="0.0176" diaginertia="1.73852e-05 1.73852e-05 1.73852e-05"/>
            <joint name="joint_l_12.0" pos="0 0 0" axis="1 0 0" range="0.263 1.396" damping="1.0" actuatorfrcrange="-0.35 0.35"/>
            <geom type="mesh" contype="0" conaffinity="0" group="1" density="0" rgba="0.2 0.2 0.2 1" mesh="link_12.0_left"/>
            <geom size="0.0179 0.017 0.02275" pos="-0.0179 0.009 0.0145" type="box" rgba="0.2 0.2 0.2 1"  group="1"/>
            <body name="link_l13.0" pos="-0.027 0.005 0.0399" quat="0.707388 0 0 -0.706825">
                <inertial pos="0 0 0" quat="-0.0269589 0.880876 0.334036 0.334292" mass="0.0119" diaginertia="4.33621e-06 4.33621e-06 4.33621e-06"/>
                <joint name="joint_l_13.0" pos="0 0 0" axis="0 0 1" range="-0.105 1.163" damping="1.0" actuatorfrcrange="-0.35 0.35"/>
                <geom type="mesh" contype="0" conaffinity="0" group="1" density="0" rgba="0.2 0.2 0.2 1" mesh="link_13.0"/>
                <geom size="0.0098 0.01375 0.00885" pos="0 0 0.00885" type="box" rgba="0.2 0.2 0.2 1"/>
                <body name="link_l14.0" pos="0 0 0.0177">
                    <inertial pos="0 0 0" quat="0.70472 0.55555 -0.174905 0.405146" mass="0.038" diaginertia="3.35111e-05 3.35111e-05 3.35111e-05"/>
                    <joint name="joint_l_14.0" pos="0 0 0" axis="0 1 0" range="-0.189 1.644" damping="1.0" actuatorfrcrange="-0.35 0.35"/>
                    <geom type="mesh" contype="0" conaffinity="0" group="1" density="0" rgba="0.2 0.2 0.2 1" mesh="link_14.0"/>
                    <geom size="0.0098 0.01375 0.0257" pos="0 0 0.0257" type="box" rgba="0.2 0.2 0.2 1"/>
                    <body name="link_l15.0" pos="0 0 0.0514">
                        <inertial pos="0 0 0.0120068" mass="0.0588" diaginertia="4.52456e-05 4.52456e-05 2.88006e-05"/>
                        <joint name="joint_l_15.0" pos="0 0 0" axis="0 1 0" range="-0.162 1.719" damping="1.0" actuatorfrcrange="-0.35 0.35"/>
                        <geom type="mesh" contype="0" conaffinity="0" group="1" density="0" rgba="0.2 0.2 0.2 1" mesh="link_15.0"/>
                        <geom size="0.0093 0.01375 0.01615" pos="0 0 0.01615" type="box" rgba="0.2 0.2 0.2 1"/>
                        <geom pos="0 0 0.0353" quat="1 0 0 0" type="mesh" contype="0" conaffinity="0" group="1" density="0" rgba="0.9 0.9 0.9 1" mesh="digit2_sensor_base"/>
                        <geom pos="0 0 0.0353" quat="1 0 0 0" type="mesh" rgba="0.9 0.9 0.9 1" mesh="digit2_sensor_base"/>
                        <geom pos="0 0 0.0353" type="mesh" contype="0" conaffinity="0" group="1" density="0" rgba="0.9 0.9 0.9 1" mesh="digit2_sensor_base_tip"/>
                        <geom pos="0 0 0.0353" type="mesh" rgba="0.9 0.9 0.9 1" mesh="digit2_sensor_base_tip"/>
                    </body>
                </body>
            </body>
        </body>
    </body>
  </worldbody>
    <actuator>
    <motor joint="joint_l_0.0" name="joint_0_drive" ctrlrange="-0.35 0.35" />
    <motor joint="joint_l_1.0" name="joint_1_drive" ctrlrange="-0.35 0.35" />
    <motor joint="joint_l_2.0" name="joint_2_drive" ctrlrange="-0.35 0.35" />
    <motor joint="joint_l_3.0" name="joint_3_drive" ctrlrange="-0.35 0.35"  />
    <motor joint="joint_l_4.0" name="joint_4_drive" ctrlrange="-0.35 0.35"  />
    <motor joint="joint_l_5.0" name="joint_5_drive" ctrlrange="-0.35 0.35"  />
    <motor joint="joint_l_6.0" name="joint_6_drive" ctrlrange="-0.35 0.35"  />
    <motor joint="joint_l_7.0" name="joint_7_drive" ctrlrange="-0.35 0.35"   />
    <motor joint="joint_l_8.0" name="joint_8_drive" ctrlrange="-0.35 0.35"  />
    <motor joint="joint_l_9.0" name="joint_9_drive" ctrlrange="-0.35 0.35"  />
    <motor joint="joint_l_10.0" name="joint_10_drive" ctrlrange="-0.35 0.35"  />
    <motor joint="joint_l_11.0" name="joint_11_drive" ctrlrange="-0.35 0.35"  />
    <motor joint="joint_l_12.0" name="joint_12_drive" ctrlrange="-0.35 0.35"  />
    <motor joint="joint_l_13.0" name="joint_13_drive" ctrlrange="0.0 0.35"   />
    <motor joint="joint_l_14.0" name="joint_14_drive" ctrlrange="-0.35 0.35"  />
    <motor joint="joint_l_15.0" name="joint_15_drive" ctrlrange="-0.35 0.35"   />
  </actuator>

    <sensor>
            <force name="force_ee" site="ft_frame"/>
            <torque name="torque_ee" site="ft_frame"/>
    </sensor>


</mujoco>
