<mujoco model="panda">
  <compiler angle="radian"/>

  <asset>
    <material name="Face636_001" shininess="0.45" rgba="0.901961 0.921569 0.929412 1"/>
    <material name="Part__Feature017_001" shininess="0.45"/>
    <material name="Part__Feature018_001" shininess="0.45"/>
    <material name="Part__Feature019_001" shininess="0.45"/>
    <material name="Part__Feature022_001" shininess="0.45" rgba="0.901961 0.921569 0.929412 1"/>
    <material name="Part__Feature023_001" shininess="0.45" rgba="0.25098 0.25098 0.25098 1"/>
    <material name="Shell001_001" shininess="0.45" rgba="0.25098 0.25098 0.25098 1"/>
    <material name="Shell002_001" shininess="0.45" rgba="0.901961 0.921569 0.929412 1"/>
    <material name="Shell003_001" shininess="0.45" rgba="0.901961 0.921569 0.929412 1"/>
    <material name="Shell009_001" shininess="0.45" rgba="0.25098 0.25098 0.25098 1"/>
    <material name="Shell010_001" shininess="0.45" rgba="0.901961 0.921569 0.929412 1"/>
    <material name="Shell_001" shininess="0.45" rgba="0.25098 0.25098 0.25098 1"/>
    <material name="Part__Feature_001" shininess="0.45"/>
    <material name="Part__Feature024" shininess="0.45"/>
    <material name="Part__Feature001_010_001_002" shininess="0.45"/>
    <material name="Part__Feature002_007_001_002" shininess="0.45"/>
    <material name="Part__Feature003_004_001_002" shininess="0.45"/>
    <material name="Part__Feature_001_001_001_002" shininess="0.45" rgba="0.25098 0.25098 0.25098 1"/>
    <material name="Part__Feature001_001_003_001" shininess="0.45"/>
    <material name="Part__Feature002_001_003_001" shininess="0.45" rgba="0.25098 0.25098 0.25098 1"/>
    <material name="Part__Feature003_001_003_001" shininess="0.45"/>
    <material name="Part__Feature_002_003_001" shininess="0.45"/>
    <material name="Part__Feature_002_004_003" shininess="0.45"/>
    <material name="Shell001_001_001_003" shininess="0.45" rgba="0.25 0.25 0.25 1"/>
    <material name="Shell_001_001_003" shininess="0.45"/>
    <material name="Face064_002_001_002_001" shininess="0.45" rgba="1 0 0 1"/>
    <material name="Face065_002_001_002_001" shininess="0.45" rgba="0 1 0 1"/>
    <material name="Face374_002_001_002_001" shininess="0.45"/>
    <material name="Face539_002_001_002_001" shininess="0.45" rgba="0.25098 0.25098 0.25098 1"/>
    <material name="Part__Feature001_009_001_002_001" shininess="0.45" rgba="0.25098 0.25098 0.25098 1"/>
    <material name="Part__Feature002_006_001_002_001" shininess="0.45" rgba="0.25098 0.25098 0.25098 1"/>
    <material name="Shell002_002_001_002_001" shininess="0.45"/>
    <material name="Shell003_002_001_002_001" shininess="0.45"/>
    <material name="Shell004_001_001_002_001" shininess="0.45"/>
    <material name="Shell005_001_001_002_001" shininess="0.45"/>
    <material name="Shell006_003_002_001" shininess="0.45" rgba="0.901961 0.921569 0.929412 1"/>
    <material name="Shell007_002_002_001" shininess="0.45" rgba="0.25 0.25 0.25 1"/>
    <material name="Shell011_002_002_001" shininess="0.45"/>
    <material name="Shell012_002_002_001" shininess="0.45"/>
    <material name="Shell_003_001_002_001" shininess="0.45" rgba="0.25098 0.25098 0.25098 1"/>
    <material name="Union001_001_001_002_001" shininess="0.45" rgba="0.039216 0.541176 0.780392 1"/>
    <material name="Union_001_001_002_001" shininess="0.45" rgba="0.039216 0.541176 0.780392 1"/>
    <material name="Part__Mirroring001_004_002" shininess="0.45" rgba="0.25098 0.25098 0.25098 1"/>
    <material name="Part__Mirroring002_004_001" shininess="0.45" rgba="0.25098 0.25098 0.25098 1"/>
    <material name="Part__Mirroring003_004_001" shininess="0.45" rgba="0.25098 0.25098 0.25098 1"/>
    <material name="Part__Mirroring004_004_002" shininess="0.45"/>
    <material name="Part__Mirroring005_004_001" shininess="0.45" rgba="0.25098 0.25098 0.25098 1"/>
    <material name="Part__Mirroring006_004_001" shininess="0.45" rgba="0.25098 0.25098 0.25098 1"/>
    <material name="Part__Mirroring007_004_001" shininess="0.45" rgba="0.25098 0.25098 0.25098 1"/>
    <material name="Part__Mirroring_004_001" shininess="0.45" rgba="0.898039 0.917647 0.929412 1"/>
    <mesh name="link0" file="meshes/link0.stl"/>
    <mesh name="link1" file="meshes/link1.stl"/>
    <mesh name="link2" file="meshes/link2.stl"/>
    <mesh name="link3" file="meshes/link3.stl"/>
    <mesh name="link4" file="meshes/link4.stl"/>
    <mesh name="link5" file="meshes/link5.stl"/>
    <mesh name="link6" file="meshes/link6.stl"/>
    <mesh name="link7" file="meshes/link7.stl"/>
    <mesh name="link0_vis_0" file="obj_meshes/link0_vis/link0_vis_0.obj"/>
    <mesh name="link0_vis_1" file="obj_meshes/link0_vis/link0_vis_1.obj"/>
    <mesh name="link0_vis_2" file="obj_meshes/link0_vis/link0_vis_2.obj"/>
    <mesh name="link0_vis_3" file="obj_meshes/link0_vis/link0_vis_3.obj"/>
    <mesh name="link0_vis_4" file="obj_meshes/link0_vis/link0_vis_4.obj"/>
    <mesh name="link0_vis_5" file="obj_meshes/link0_vis/link0_vis_5.obj"/>
    <mesh name="link0_vis_6" file="obj_meshes/link0_vis/link0_vis_6.obj"/>
    <mesh name="link0_vis_7" file="obj_meshes/link0_vis/link0_vis_7.obj"/>
    <mesh name="link0_vis_8" file="obj_meshes/link0_vis/link0_vis_8.obj"/>
    <mesh name="link0_vis_9" file="obj_meshes/link0_vis/link0_vis_9.obj"/>
    <mesh name="link0_vis_10" file="obj_meshes/link0_vis/link0_vis_10.obj"/>
    <mesh name="link0_vis_11" file="obj_meshes/link0_vis/link0_vis_11.obj"/>
    <mesh name="link1_vis" file="obj_meshes/link1_vis/link1_vis.obj"/>
    <mesh name="link2_vis" file="obj_meshes/link2_vis/link2_vis.obj"/>
    <mesh name="link3_vis_0" file="obj_meshes/link3_vis/link3_vis_0.obj"/>
    <mesh name="link3_vis_1" file="obj_meshes/link3_vis/link3_vis_1.obj"/>
    <mesh name="link3_vis_2" file="obj_meshes/link3_vis/link3_vis_2.obj"/>
    <mesh name="link3_vis_3" file="obj_meshes/link3_vis/link3_vis_3.obj"/>
    <mesh name="link4_vis_0" file="obj_meshes/link4_vis/link4_vis_0.obj"/>
    <mesh name="link4_vis_1" file="obj_meshes/link4_vis/link4_vis_1.obj"/>
    <mesh name="link4_vis_2" file="obj_meshes/link4_vis/link4_vis_2.obj"/>
    <mesh name="link4_vis_3" file="obj_meshes/link4_vis/link4_vis_3.obj"/>
    <mesh name="link5_vis_0" file="obj_meshes/link5_vis/link5_vis_0.obj"/>
    <mesh name="link5_vis_1" file="obj_meshes/link5_vis/link5_vis_1.obj"/>
    <mesh name="link5_vis_2" file="obj_meshes/link5_vis/link5_vis_2.obj"/>
    <mesh name="link6_vis_0" file="obj_meshes/link6_vis/link6_vis_0.obj"/>
    <mesh name="link6_vis_1" file="obj_meshes/link6_vis/link6_vis_1.obj"/>
    <mesh name="link6_vis_2" file="obj_meshes/link6_vis/link6_vis_2.obj"/>
    <mesh name="link6_vis_3" file="obj_meshes/link6_vis/link6_vis_3.obj"/>
    <mesh name="link6_vis_4" file="obj_meshes/link6_vis/link6_vis_4.obj"/>
    <mesh name="link6_vis_5" file="obj_meshes/link6_vis/link6_vis_5.obj"/>
    <mesh name="link6_vis_6" file="obj_meshes/link6_vis/link6_vis_6.obj"/>
    <mesh name="link6_vis_7" file="obj_meshes/link6_vis/link6_vis_7.obj"/>
    <mesh name="link6_vis_8" file="obj_meshes/link6_vis/link6_vis_8.obj"/>
    <mesh name="link6_vis_9" file="obj_meshes/link6_vis/link6_vis_9.obj"/>
    <mesh name="link6_vis_10" file="obj_meshes/link6_vis/link6_vis_10.obj"/>
    <mesh name="link6_vis_11" file="obj_meshes/link6_vis/link6_vis_11.obj"/>
    <mesh name="link6_vis_12" file="obj_meshes/link6_vis/link6_vis_12.obj"/>
    <mesh name="link6_vis_13" file="obj_meshes/link6_vis/link6_vis_13.obj"/>
    <mesh name="link6_vis_14" file="obj_meshes/link6_vis/link6_vis_14.obj"/>
    <mesh name="link6_vis_15" file="obj_meshes/link6_vis/link6_vis_15.obj"/>
    <mesh name="link6_vis_16" file="obj_meshes/link6_vis/link6_vis_16.obj"/>
    <mesh name="link7_vis_0" file="obj_meshes/link7_vis/link7_vis_0.obj"/>
    <mesh name="link7_vis_1" file="obj_meshes/link7_vis/link7_vis_1.obj"/>
    <mesh name="link7_vis_2" file="obj_meshes/link7_vis/link7_vis_2.obj"/>
    <mesh name="link7_vis_3" file="obj_meshes/link7_vis/link7_vis_3.obj"/>
    <mesh name="link7_vis_4" file="obj_meshes/link7_vis/link7_vis_4.obj"/>
    <mesh name="link7_vis_5" file="obj_meshes/link7_vis/link7_vis_5.obj"/>
    <mesh name="link7_vis_6" file="obj_meshes/link7_vis/link7_vis_6.obj"/>
    <mesh name="link7_vis_7" file="obj_meshes/link7_vis/link7_vis_7.obj"/>
  </asset>

  <worldbody>
    <body name="base">
      <inertial pos="0 0 0" mass="0" diaginertia="0 0 0"/>
      <camera name="robotview" pos="1 0 0.4" quat="0.653098 0.271041 0.271041 0.653098"/>
      <body name="link0">
        <inertial pos="0 0 0.05" mass="4" diaginertia="0.4 0.4 0.4"/>
        <geom type="mesh" contype="0" conaffinity="0" group="1" material="Shell010_001" mesh="link0_vis_0"/>
        <geom type="mesh" contype="0" conaffinity="0" group="1" material="Shell009_001" mesh="link0_vis_1"/>
        <geom type="mesh" contype="0" conaffinity="0" group="1" material="Shell003_001" mesh="link0_vis_2"/>
        <geom type="mesh" contype="0" conaffinity="0" group="1" material="Shell_001" mesh="link0_vis_3"/>
        <geom type="mesh" contype="0" conaffinity="0" group="1" material="Shell002_001" mesh="link0_vis_4"/>
        <geom type="mesh" contype="0" conaffinity="0" group="1" material="Shell001_001" mesh="link0_vis_5"/>
        <geom type="mesh" contype="0" conaffinity="0" group="1" material="Face636_001" mesh="link0_vis_6"/>
        <geom type="mesh" contype="0" conaffinity="0" group="1" material="Part__Feature018_001" mesh="link0_vis_7"/>
        <geom type="mesh" contype="0" conaffinity="0" group="1" material="Part__Feature019_001" mesh="link0_vis_8"/>
        <geom type="mesh" contype="0" conaffinity="0" group="1" material="Part__Feature023_001" mesh="link0_vis_9"/>
        <geom type="mesh" contype="0" conaffinity="0" group="1" material="Part__Feature022_001" mesh="link0_vis_10"/>
        <geom type="mesh" contype="0" conaffinity="0" group="1" material="Part__Feature017_001" mesh="link0_vis_11"/>
        <geom name="link0_collision" type="mesh" mesh="link0"/>
        <site name="right_center" pos="0 0 0" size="0.01" group="2" rgba="1 0.3 0.3 1"/>
        <body name="link1" pos="0 0 0.333">
          <inertial pos="0 0 -0.07" mass="3" diaginertia="0.3 0.3 0.3"/>
          <joint name="joint1" pos="0 0 0" axis="0 0 1" limited="true" range="-2.8973 2.8973" damping="0.1"/>
          <geom type="mesh" contype="0" conaffinity="0" group="1" material="Part__Feature_001" mesh="link1_vis"/>
          <geom name="link1_collision" type="mesh" mesh="link1"/>
          <body name="link2" quat="0.707107 -0.707107 0 0">
            <inertial pos="0 -0.1 0" mass="3" diaginertia="0.3 0.3 0.3"/>
            <joint name="joint2" pos="0 0 0" axis="0 0 1" limited="true" range="-1.7628 1.7628" damping="0.1"/>
            <geom type="mesh" contype="0" conaffinity="0" group="1" material="Part__Feature024" mesh="link2_vis"/>
            <geom name="link2_collision" type="mesh" mesh="link2"/>
            <body name="link3" pos="0 -0.316 0" quat="0.707107 0.707107 0 0">
              <inertial pos="0.04 0 -0.05" mass="2" diaginertia="0.2 0.2 0.2"/>
              <joint name="joint3" pos="0 0 0" axis="0 0 1" limited="true" range="-2.8973 2.8973" damping="0.1"/>
              <geom type="mesh" contype="0" conaffinity="0" group="1" material="Part__Feature003_004_001_002" mesh="link3_vis_0"/>
              <geom type="mesh" contype="0" conaffinity="0" group="1" material="Part__Feature002_007_001_002" mesh="link3_vis_1"/>
              <geom type="mesh" contype="0" conaffinity="0" group="1" material="Part__Feature001_010_001_002" mesh="link3_vis_2"/>
              <geom type="mesh" contype="0" conaffinity="0" group="1" material="Part__Feature_001_001_001_002" mesh="link3_vis_3"/>
              <geom name="link3_collision" type="mesh" mesh="link3"/>
              <body name="link4" pos="0.0825 0 0" quat="0.707107 0.707107 0 0">
                <inertial pos="-0.04 0.05 0" mass="2" diaginertia="0.2 0.2 0.2"/>
                <joint name="joint4" pos="0 0 0" axis="0 0 1" limited="true" range="-3.0718 -0.0698" damping="0.1"/>
                <geom type="mesh" contype="0" conaffinity="0" group="1" material="Part__Feature001_001_003_001" mesh="link4_vis_0"/>
                <geom type="mesh" contype="0" conaffinity="0" group="1" material="Part__Feature003_001_003_001" mesh="link4_vis_1"/>
                <geom type="mesh" contype="0" conaffinity="0" group="1" material="Part__Feature002_001_003_001" mesh="link4_vis_2"/>
                <geom type="mesh" contype="0" conaffinity="0" group="1" material="Part__Feature_002_003_001" mesh="link4_vis_3"/>
                <geom name="link4_collision" type="mesh" mesh="link4"/>
                <body name="link5" pos="-0.0825 0.384 0" quat="0.707107 -0.707107 0 0">
                  <inertial pos="0 0 -0.15" mass="2" diaginertia="0.2 0.2 0.2"/>
                  <joint name="joint5" pos="0 0 0" axis="0 0 1" limited="true" range="-2.8973 2.8973" damping="0.1"/>
                  <geom type="mesh" contype="0" conaffinity="0" group="1" material="Shell001_001_001_003" mesh="link5_vis_0"/>
                  <geom type="mesh" contype="0" conaffinity="0" group="1" material="Shell_001_001_003" mesh="link5_vis_1"/>
                  <geom type="mesh" contype="0" conaffinity="0" group="1" material="Part__Feature_002_004_003" mesh="link5_vis_2"/>
                  <geom name="link5_collision" type="mesh" mesh="link5"/>
                  <body name="link6" quat="0.707107 0.707107 0 0">
                    <inertial pos="0.06 0 0" mass="1.5" diaginertia="0.1 0.1 0.1"/>
                    <joint name="joint6" pos="0 0 0" axis="0 0 1" limited="true" range="-0.0175 3.7525" damping="0.01"/>
                    <geom type="mesh" contype="0" conaffinity="0" group="1" material="Shell006_003_002_001" mesh="link6_vis_0"/>
                    <geom type="mesh" contype="0" conaffinity="0" group="1" material="Shell011_002_002_001" mesh="link6_vis_1"/>
                    <geom type="mesh" contype="0" conaffinity="0" group="1" material="Shell007_002_002_001" mesh="link6_vis_2"/>
                    <geom type="mesh" contype="0" conaffinity="0" group="1" material="Shell005_001_001_002_001" mesh="link6_vis_3"/>
                    <geom type="mesh" contype="0" conaffinity="0" group="1" material="Shell004_001_001_002_001" mesh="link6_vis_4"/>
                    <geom type="mesh" contype="0" conaffinity="0" group="1" material="Shell003_002_001_002_001" mesh="link6_vis_5"/>
                    <geom type="mesh" contype="0" conaffinity="0" group="1" material="Shell002_002_001_002_001" mesh="link6_vis_6"/>
                    <geom type="mesh" contype="0" conaffinity="0" group="1" material="Union001_001_001_002_001" mesh="link6_vis_7"/>
                    <geom type="mesh" contype="0" conaffinity="0" group="1" material="Union_001_001_002_001" mesh="link6_vis_8"/>
                    <geom type="mesh" contype="0" conaffinity="0" group="1" material="Face539_002_001_002_001" mesh="link6_vis_9"/>
                    <geom type="mesh" contype="0" conaffinity="0" group="1" material="Shell_003_001_002_001" mesh="link6_vis_10"/>
                    <geom type="mesh" contype="0" conaffinity="0" group="1" material="Face374_002_001_002_001" mesh="link6_vis_11"/>
                    <geom type="mesh" contype="0" conaffinity="0" group="1" material="Face065_002_001_002_001" mesh="link6_vis_12"/>
                    <geom type="mesh" contype="0" conaffinity="0" group="1" material="Face064_002_001_002_001" mesh="link6_vis_13"/>
                    <geom type="mesh" contype="0" conaffinity="0" group="1" material="Part__Feature002_006_001_002_001" mesh="link6_vis_14"/>
                    <geom type="mesh" contype="0" conaffinity="0" group="1" material="Part__Feature001_009_001_002_001" mesh="link6_vis_15"/>
                    <geom type="mesh" contype="0" conaffinity="0" group="1" material="Shell012_002_002_001" mesh="link6_vis_16"/>
                    <geom name="link6_collision" type="mesh" mesh="link6"/>
                    <body name="link7" pos="0.088 0 0" quat="0.707107 0.707107 0 0">
                      <inertial pos="0 0 0.08" mass="0.5" diaginertia="0.05 0.05 0.05"/>
                      <joint name="joint7" pos="0 0 0" axis="0 0 1" limited="true" range="-2.8973 2.8973" damping="0.01"/>
                      <geom type="mesh" contype="0" conaffinity="0" group="1" material="Part__Mirroring004_004_002" mesh="link7_vis_0"/>
                      <geom type="mesh" contype="0" conaffinity="0" group="1" material="Part__Mirroring001_004_002" mesh="link7_vis_1"/>
                      <geom type="mesh" contype="0" conaffinity="0" group="1" material="Part__Mirroring007_004_001" mesh="link7_vis_2"/>
                      <geom type="mesh" contype="0" conaffinity="0" group="1" material="Part__Mirroring006_004_001" mesh="link7_vis_3"/>
                      <geom type="mesh" contype="0" conaffinity="0" group="1" material="Part__Mirroring005_004_001" mesh="link7_vis_4"/>
                      <geom type="mesh" contype="0" conaffinity="0" group="1" material="Part__Mirroring003_004_001" mesh="link7_vis_5"/>
                      <geom type="mesh" contype="0" conaffinity="0" group="1" material="Part__Mirroring002_004_001" mesh="link7_vis_6"/>
                      <geom type="mesh" contype="0" conaffinity="0" group="1" material="Part__Mirroring_004_001" mesh="link7_vis_7"/>
                      <geom name="link7_collision" type="mesh" mesh="link7"/>
                      <body name="right_hand" pos="0 0 0.1065" quat="0.923785 0 0 -0.382911">
                        <inertial pos="0 0 0" mass="0.5" diaginertia="0.05 0.05 0.05"/>
                        <camera name="eye_in_hand" pos="0.05 0 0" quat="0 0.707107 0.707107 0" fovy="75"/>
                      </body>
                    </body>
                  </body>
                </body>
              </body>
            </body>
          </body>
        </body>
      </body>
    </body>
  </worldbody>

  <actuator>
    <general name="torq_j1" joint="joint1" ctrllimited="true" ctrlrange="-80 80"/>
    <general name="torq_j2" joint="joint2" ctrllimited="true" ctrlrange="-80 80"/>
    <general name="torq_j3" joint="joint3" ctrllimited="true" ctrlrange="-80 80"/>
    <general name="torq_j4" joint="joint4" ctrllimited="true" ctrlrange="-80 80"/>
    <general name="torq_j5" joint="joint5" ctrllimited="true" ctrlrange="-80 80"/>
    <general name="torq_j6" joint="joint6" ctrllimited="true" ctrlrange="-12 12"/>
    <general name="torq_j7" joint="joint7" ctrllimited="true" ctrlrange="-12 12"/>
  </actuator>
</mujoco>
