<mujoco model="tmr">
  <compiler angle="radian"/>

  <asset>
    <mesh name="tmr_base" file="meshes/murp/tmr_base.stl"/>
    <mesh name="torso_cover" file="meshes/murp/torso.stl"/>
    <mesh name="caster" file="meshes/murp/caster.stl"/>
    <mesh name="wheel_simplified" file="meshes/murp/wheel.stl"/>
  </asset>
  <actuator>
    <velocity ctrllimited="true" ctrlrange="-1.00 1.00" joint="joint_mobile_forward" kv="1000" name="actuator_mobile_forward" forcelimited="true" forcerange="-600 1600"/>
		<velocity ctrllimited="true" ctrlrange="-1.00 1.00" joint="joint_mobile_side" kv="1000" name="actuator_mobile_side" forcelimited="true" forcerange="-600 1600"/>
		<velocity ctrllimited="true" ctrlrange="-1.50 1.50" joint="joint_mobile_yaw" kv="1500" name="actuator_mobile_yaw" forcelimited="true" forcerange="-600 1600"/>
    <!-- <velocity ctrllimited="true" ctrlrange="-1.50 1.50" joint="caster_front_left_steering_joint" kv="1500" name="caster_fl" forcelimited="true" forcerange="0 0"/>
    <velocity ctrllimited="true" ctrlrange="-1.50 1.50" joint="caster_front_left_joint" kv="1500" name="caster_front_left_joint" forcelimited="true" forcerange="0 0"/>
    <velocity ctrllimited="true" ctrlrange="-1.50 1.50" joint="bogie_left_joint" kv="1500" name="bogie_left_joint" forcelimited="true" forcerange="0 0"/>
    <velocity ctrllimited="true" ctrlrange="-1.50 1.50" joint="l_wheel_joint" kv="1500" name="l_wheel_link" forcelimited="true" forcerange="0 0"/>
    <velocity ctrllimited="true" ctrlrange="-1.50 1.50" joint="caster_rear_left_steering_joint" kv="1500" name="caster_rear_left_steering_joint" forcelimited="true" forcerange="0 0"/>
    <velocity ctrllimited="true" ctrlrange="-1.50 1.50" joint="caster_rear_left_joint" kv="1500" name="caster_rear_left_joint" forcelimited="true" forcerange="0 0"/>
    <velocity ctrllimited="true" ctrlrange="-1.50 1.50" joint="bogie_right_joint" kv="1500" name="bogie_right_joint" forcelimited="true" forcerange="0 0"/>
    <velocity ctrllimited="true" ctrlrange="-1.50 1.50" joint="r_wheel_joint" kv="1500" name="r_wheel_joint" forcelimited="true" forcerange="0 0"/>
    <velocity ctrllimited="true" ctrlrange="-1.50 1.50" joint="caster_rear_right_steering_joint" kv="1500" name="caster_rear_right_steering_joint" forcelimited="true" forcerange="0 0"/>
    <velocity ctrllimited="true" ctrlrange="-1.50 1.50" joint="caster_rear_right_joint" kv="1500" name="caster_rear_right_joint" forcelimited="true" forcerange="0 0"/> -->


		<!-- <motor ctrllimited="true" ctrlrange="-100000.0 100000.0" joint="joint_torso_height" name="actuator_torso_height" forcelimited="false"/> -->
	</actuator>

  <worldbody>
    <body name="base" pos="0 0 0">
        <inertial pos="0 0 0" mass="75.0" diaginertia="0.1 0.1 0.1"/>
        <geom pos="0 0 0.2" quat="0 0 0 1" type="mesh" rgba="1 1 1 1" mesh="tmr_base" group="1"/>
        <!-- <geom pos="0.295 0.26 0.050" quat="0.5 0.5 0.5 0.5" type="mesh" rgba="0.3 0.3 0.3 1" mesh="caster" group="1"/> -->
        <!-- <geom pos="0.295 -0.26 0.050" quat="0.5 0.5 0.5 0.5" type="mesh" rgba="0.3 0.3 0.3 1" mesh="caster" group="1"/> -->
        <!-- <geom pos="0 0.25 0.120" quat="0 1 0 0" type="mesh" rgba="0.3 0.3 0.3 1" mesh="wheel_simplified" group="1"/> -->
        <!-- <geom pos="0 -0.25 0.120" quat="0 1 0 0" type="mesh" rgba="0.3 0.3 0.3 1" mesh="wheel_simplified" group="1"/> -->
        <!-- <geom pos="-0.165 0.01 -0.025" quat="0.5 0.5 0.5 0.5" type="mesh" rgba="0.3 0.3 0.3 1" mesh="caster" group="1"/> -->
        <!-- <geom pos="-0.165 -0.01 -0.025" quat="0.5 0.5 0.5 0.5" type="mesh" rgba="0.3 0.3 0.3 1" mesh="caster" group="1"/> -->

        <body name="fixed_support" pos="0.00 0 0.00">
          <body name="support" pos="0.0 0.0 0">
            <site name="center" type="sphere" pos="0 0 0" size="0.01" group="1" rgba="0 0 0 0"/>      
          </body>
        </body>
        
        <!-- <body name="caster_front_left_fixed_link" pos="0.33 0.26 0.124"> -->
          <!-- <inertial pos="0 0 0" quat="0 0.707107 0 0.707107" mass="0.5" diaginertia="0.000104167 6.70417e-05 3.7875e-05"/> -->
          <!-- <joint name="caster_front_left_steering_joint" pos="0 0 0" axis="0 0 1" actuatorfrcrange="-500 500" damping="0.003"/> -->
          <!-- <body name="caster_front_left_link" pos="-0.035 0 -0.074"> -->
            <!-- <inertial pos="0 0 0" quat="0.5 0.5 -0.5 0.5" mass="0.5" diaginertia="0.000625 0.000338542 0.000338542"/> -->
            <!-- <joint name="caster_front_left_joint" pos="0 0 0" axis="0 1 0" actuatorfrcrange="-500 500" damping="0.003"/> -->
            <!-- <geom quat="0.5 0.5 0.5 0.5" type="mesh" rgba="0.3 0.3 0.3 1" mesh="caster" group="1"/> -->
          <!-- </body> -->
        <!-- </body> -->
        <!-- <body name="caster_front_right_fixed_link" pos="0.33 -0.26 0.124"> -->
          <!-- <inertial pos="0 0 0" quat="0 0.707107 0 0.707107" mass="0.5" diaginertia="0.000104167 6.70417e-05 3.7875e-05"/> -->
          <!-- <joint name="caster_front_right_steering_joint" pos="0 0 0" axis="0 0 1" actuatorfrcrange="-500 500" damping="0.003"/> -->
          <!-- <body name="caster_front_right_link" pos="-0.035 0 -0.074"> -->
            <!-- <inertial pos="0 0 0" quat="0.5 0.5 -0.5 0.5" mass="0.5" diaginertia="0.000625 0.000338542 0.000338542"/> -->
            <!-- <joint name="caster_front_right_joint" pos="0 0 0" axis="0 1 0" actuatorfrcrange="-500 500" damping="0.003"/> -->
            <!-- <geom quat="0.5 0.5 0.5 0.5" type="mesh" rgba="0.3 0.3 0.3 1" mesh="caster" group="1"/> -->
          <!-- </body> -->
        <!-- </body> -->
        <!-- <body name="bogie_left_link" pos="-0.18 0.25 0.075"> -->
          <!-- <inertial pos="0 0 0" quat="0.707107 0 0 0.707107" mass="3" diaginertia="0.0257 0.0256563 0.00015625"/> -->
          <!-- <joint name="bogie_left_joint" pos="0 0 0" axis="0 1 0" range="-0.16 0.18" actuatorfrcrange="-500 500" damping="0.003"/> -->
          <!-- <body name="l_wheel_link" pos="0.18 0.015 0.045"> -->
            <!-- <inertial pos="0 0 0" quat="0.5 0.5 -0.5 0.5" mass="1" diaginertia="0.0072 0.00413333 0.00413333"/> -->
            <!-- <joint name="l_wheel_joint" pos="0 0 0" axis="0 1 0" actuatorfrcrange="-25 25"/> -->
            <!-- <geom quat="0 1 0 0" type="mesh" rgba="0.3 0.3 0.3 1" mesh="wheel_simplified" group="1"/> -->
          <!-- </body> -->
          <!-- <body name="caster_rear_left_fixed_link" pos="-0.13 0.01 0.049"> -->
            <!-- <inertial pos="0 0 0" quat="0 0.707107 0 0.707107" mass="0.5" diaginertia="0.000104167 6.70417e-05 3.7875e-05"/> -->
            <!-- <joint name="caster_rear_left_steering_joint" pos="0 0 0" axis="0 0 1" actuatorfrcrange="-500 500" damping="0.003"/> -->
            <!-- <body name="caster_rear_left_link" pos="-0.035 0 -0.074"> -->
              <!-- <inertial pos="0 0 0" quat="0.5 0.5 -0.5 0.5" mass="0.5" diaginertia="0.000625 0.000338542 0.000338542"/> -->
              <!-- <joint name="caster_rear_left_joint" pos="0 0 0" axis="0 1 0" actuatorfrcrange="-500 500" damping="0.003"/> -->
              <!-- <geom quat="0.5 0.5 0.5 0.5" type="mesh" rgba="0.3 0.3 0.3 1" mesh="caster"/> -->
            <!-- </body> -->
          <!-- </body> -->
        <!-- </body> -->
        <!-- <body name="bogie_right_link" pos="-0.18 -0.25 0.075"> -->
          <!-- <inertial pos="0 0 0" quat="0.707107 0 0 0.707107" mass="3" diaginertia="0.0257 0.0256563 0.00015625"/> -->
          <!-- <joint name="bogie_right_joint" pos="0 0 0" axis="0 1 0" range="-0.16 0.18" actuatorfrcrange="-500 500" damping="0.003"/> -->
          <!-- <body name="r_wheel_link" pos="0.18 -0.015 0.045"> -->
            <!-- <inertial pos="0 0 0" quat="0.5 0.5 -0.5 0.5" mass="1" diaginertia="0.0072 0.00413333 0.00413333"/> -->
            <!-- <joint name="r_wheel_joint" pos="0 0 0" axis="0 1 0" actuatorfrcrange="-25 25"/> -->
            <!-- <geom type="mesh" rgba="0.3 0.3 0.3 1" mesh="wheel_simplified"/> -->
          <!-- </body> -->
          <!-- <body name="caster_rear_right_fixed_link" pos="-0.13 -0.01 0.049"> -->
            <!-- <inertial pos="0 0 0" quat="0 0.707107 0 0.707107" mass="0.5" diaginertia="0.000104167 6.70417e-05 3.7875e-05"/> -->
            <!-- <joint name="caster_rear_right_steering_joint" pos="0 0 0" axis="0 0 1" actuatorfrcrange="-500 500" damping="0.003"/> -->
            <!-- <body name="caster_rear_right_link" pos="-0.035 0 -0.074"> -->
              <!-- <inertial pos="0 0 0" quat="0.5 0.5 -0.5 0.5" mass="0.5" diaginertia="0.000625 0.000338542 0.000338542"/> -->
              <!-- <joint name="caster_rear_right_joint" pos="0 0 0" axis="0 1 0" actuatorfrcrange="-500 500" damping="0.003"/> -->
              <!-- <geom quat="0.5 0.5 0.5 0.5" type="mesh" rgba="0.3 0.3 0.3 1" mesh="caster"/> -->
            <!-- </body> -->
          <!-- </body> -->
        <!-- </body> -->
        <joint name="joint_mobile_forward" pos="-0.21 0 0" axis="0 1 0" type="slide" limited="false" damping="0" armature="0.0" frictionloss="250"/>
        <joint name="joint_mobile_side" pos="-0.21 0 0" axis="1 0 0" type="slide" limited="false" damping="0" armature="0.0" frictionloss="250"/>
        <joint name="joint_mobile_yaw" pos="-0.21 0 0" axis="0 0 1" type="hinge" limited="false" damping="0" armature="0.0" frictionloss="250"/>
    </body>
  </worldbody>
</mujoco>
