<?xml version="1.0" ?>
<!-- =================================================================================== -->
<!-- |    This document was autogenerated by xacro from robots/tmr.urdf.xacro          | -->
<!-- |    EDITING THIS FILE BY HAND IS NOT RECOMMENDED                                 | -->
<!-- =================================================================================== -->
<robot name="tmr" xmlns:controller="http://playerstage.sourceforge.net/gazebo/xmlschema/#controller" xmlns:interface="http://playerstage.sourceforge.net/gazebo/xmlschema/#interface" xmlns:sensor="http://playerstage.sourceforge.net/gazebo/xmlschema/#sensor">
  <!-- ========================================= -->
  <!-- ||         Inertia Utilities           || -->
  <!-- ========================================= -->
  <!-- ========================================= -->
  <!-- ||         Inertia Utilities           || -->
  <!-- ========================================= -->
  <!-- ========================================= -->
  <!-- ||         Inertia Utilities           || -->
  <!-- ========================================= -->
  <!-- ========================================= -->
  <!-- ||         Inertia Utilities           || -->
  <!-- ========================================= -->
  <material name="aluminum">
    <color rgba="0.5 0.5 0.5 1"/>
  </material>
  <material name="plastic">
    <color rgba="0.1 0.1 0.1 1"/>
  </material>
  <!-- Main Platform Chassis -->
  <link name="base_link">
    <visual>
      <origin rpy="0 0 3.141592653589793" xyz="0 0 0"/>
      <geometry>
        <mesh filename="meshes/murp/tmr_base.stl"/>
      </geometry>
      <material name="white">
        <color rgba="1.0 1.0 1.0 1.0"/>
      </material>
    </visual>
    <collision>
      <origin rpy="0 0 3.141592653589793" xyz="0 0 0"/>
      <geometry>
        <mesh filename="meshes/murp/tmr_base.stl"/>
      </geometry>
    </collision>
  </link>
  <link name="base_inertia">
    <inertial>
      <mass value="75"/>
      <inertia ixx="4.540225" ixy="0" ixz="0" iyy="6.06640625" iyz="0" izz="2.6066312499999995"/>
    </inertial>
  </link>
  <joint name="base_inertia_joint" type="fixed">
    <parent link="base_link"/>
    <child link="base_inertia"/>
  </joint>
  <link name="torso_link">
    <visual>
      <geometry>
        <mesh filename="meshes/murp/torso_cover.obj"/>
      </geometry>
      <material name="white">
        <color rgba="1.0 1.0 1.0 1.0"/>
      </material>
    </visual>
    <collision>
      <geometry>
        <mesh filename="meshes/murp/torso_cover.obj"/>
      </geometry>
    </collision>
    <inertial>
      <origin rpy="0 0 0" xyz="-0.374101 0.001522 0.120542"/>
      <mass value="75.711368"/>
      <inertia ixx="1.822241406454" ixy="0.009367998445" ixz="0.855091055826" iyx="0.009367998445" iyy="4.242134556907" iyz="-0.012022054390" izx="0.855091055826" izy="-0.012022054390" izz="4.568496104964"/>
    </inertial>
  </link>
  <joint name="torso_joint" type="fixed">
    <origin rpy="0 0 0" xyz="0.212 0 0.294"/>
    <parent link="base_link"/>
    <child link="torso_link"/>
  </joint>
  <link name="caster_front_left_fixed_link">
    <visual>
      <origin xyz="0 0 -0.0015"/>
      <geometry>
        <box size="0.04 0.03 0.003"/>
      </geometry>
      <material name="darkgrey">
        <color rgba="0.3 0.3 0.3 1.0"/>
      </material>
    </visual>
    <inertial>
      <mass value="0.5"/>
      <inertia ixx="3.7875e-05" ixy="0" ixz="0" iyy="6.704166666666667e-05" iyz="0" izz="0.00010416666666666666"/>
    </inertial>
  </link>
  </joint>
  <joint name="caster_front_left_steering_joint" type="continuous">
    <origin xyz="0.33 0.26 0.124"/>
    <parent link="base_link"/>
    <child link="caster_front_left_fixed_link"/>
    <axis xyz="0 0 1"/>
    <limit effort="500" velocity="20"/>
    <dynamics damping="0.003" friction="0.0"/>
  </joint>
  <link name="caster_front_left_link">
    <visual>
      <origin rpy="1.5707963267948966 0 1.5707963267948966"/>
      <geometry>
        <mesh filename="meshes/murp/caster.stl"/>
      </geometry>
      <material name="darkgrey">
        <color rgba="0.3 0.3 0.3 1.0"/>
      </material>
    </visual>
    <collision>
      <origin rpy="1.5707963267948966 0 1.5707963267948966"/>
      <geometry>
        <mesh filename="meshes/murp/caster.stl"/>
      </geometry>
      <material name="darkgrey">
        <color rgba="0.3 0.3 0.3 1.0"/>
      </material>
    </collision>
    <inertial>
      <mass value="0.5"/>
      <inertia ixx="0.00033854166666666673" ixy="0" ixz="0" iyy="0.00033854166666666673" iyz="0" izz="0.0006250000000000001"/>
    </inertial>
  </link>
  <joint name="caster_front_left_joint" type="continuous">
    <origin rpy="0 0 0" xyz="-0.035 0 -0.074"/>
    <parent link="caster_front_left_fixed_link"/>
    <child link="caster_front_left_link"/>
    <axis xyz="0 1 0"/>
    <limit effort="500" velocity="20"/>
    <dynamics damping="0.003" friction="0.0"/>
  </joint>
  <link name="caster_front_right_fixed_link">
    <visual>
      <origin xyz="0 0 -0.0015"/>
      <geometry>
        <box size="0.04 0.03 0.003"/>
      </geometry>
      <material name="darkgrey">
        <color rgba="0.3 0.3 0.3 1.0"/>
      </material>
    </visual>
    <inertial>
      <mass value="0.5"/>
      <inertia ixx="3.7875e-05" ixy="0" ixz="0" iyy="6.704166666666667e-05" iyz="0" izz="0.00010416666666666666"/>
    </inertial>
  </link>
  <joint name="caster_front_right_steering_joint" type="continuous">
    <origin xyz="0.33 -0.26 0.124"/>
    <parent link="base_link"/>
    <child link="caster_front_right_fixed_link"/>
    <axis xyz="0 0 1"/>
    <limit effort="500" velocity="20"/>
    <dynamics damping="0.003" friction="0.0"/>
  </joint>
  <link name="caster_front_right_link">
    <visual>
      <origin rpy="1.5707963267948966 0 1.5707963267948966"/>
      <geometry>
        <mesh filename="meshes/murp/caster.stl"/>
      </geometry>
      <material name="darkgrey">
        <color rgba="0.3 0.3 0.3 1.0"/>
      </material>
    </visual>
    <collision>
      <origin rpy="1.5707963267948966 0 1.5707963267948966"/>
      <geometry>
        <mesh filename="meshes/murp/caster.stl"/>
      </geometry>
      <material name="darkgrey">
        <color rgba="0.3 0.3 0.3 1.0"/>
      </material>
    </collision>
    <inertial>
      <mass value="0.5"/>
      <inertia ixx="0.00033854166666666673" ixy="0" ixz="0" iyy="0.00033854166666666673" iyz="0" izz="0.0006250000000000001"/>
    </inertial>
  </link>
  <joint name="caster_front_right_joint" type="continuous">
    <origin rpy="0 0 0" xyz="-0.035 0 -0.074"/>
    <parent link="caster_front_right_fixed_link"/>
    <child link="caster_front_right_link"/>
    <axis xyz="0 1 0"/>
    <limit effort="500" velocity="20"/>
    <dynamics damping="0.003" friction="0.0"/>
  </joint>
  <link name="bogie_left_link">
    <visual>
      <origin rpy="1.5707963267948966 0 0"/>
      <geometry>
        <cylinder length="0.0225" radius="0.015"/>
      </geometry>
      <material name="darkgrey">
        <color rgba="0.3 0.3 0.3 1.0"/>
      </material>
    </visual>
    <inertial>
      <mass value="3"/>
      <inertia ixx="0.025656250000000002" ixy="0" ixz="0" iyy="0.0257" iyz="0" izz="0.00015625"/>
    </inertial>
  </link>
  <joint name="bogie_left_joint" type="revolute">
    <origin xyz="-0.18 0.25 0.075"/>
    <parent link="base_link"/>
    <child link="bogie_left_link"/>
    <axis xyz="0 1 0"/>
    <limit effort="500" lower="-0.16" upper="0.18" velocity="20"/>
    <dynamics damping="0.003" friction="0.0"/>
  </joint>
  <link name="l_wheel_link">
    <visual>
      <origin rpy="3.141592653589793 0 0"/>
      <geometry>
        <mesh filename="meshes/murp/wheel.stl"/>
      </geometry>
      <material name="darkgrey">
        <color rgba="0.3 0.3 0.3 1.0"/>
      </material>
    </visual>
    <collision>
      <origin rpy="3.141592653589793 0 0"/>
      <geometry>
        <mesh filename="tmr_description/meshes/collision/wheel_simplified.stl"/>
      </geometry>
    </collision>
    <inertial>
      <mass value="1"/>
      <inertia ixx="0.0041333333333333335" ixy="0" ixz="0" iyy="0.0041333333333333335" iyz="0" izz="0.0072"/>
    </inertial>
  </link>
  <joint name="l_wheel_joint" type="continuous">
    <origin xyz="0.18 0.015 0.045"/>
    <parent link="bogie_left_link"/>
    <child link="l_wheel_link"/>
    <axis xyz="0 1 0"/>
    <limit effort="25" velocity="20"/>
  </joint>
  <link name="caster_rear_left_fixed_link">
    <visual>
      <origin xyz="0 0 -0.0015"/>
      <geometry>
        <box size="0.04 0.03 0.003"/>
      </geometry>
      <material name="darkgrey">
        <color rgba="0.3 0.3 0.3 1.0"/>
      </material>
    </visual>
    <inertial>
      <mass value="0.5"/>
      <inertia ixx="3.7875e-05" ixy="0" ixz="0" iyy="6.704166666666667e-05" iyz="0" izz="0.00010416666666666666"/>
    </inertial>
  </link>
  <joint name="caster_rear_left_steering_joint" type="continuous">
    <origin xyz="-0.13 0.01 0.049"/>
    <parent link="bogie_left_link"/>
    <child link="caster_rear_left_fixed_link"/>
    <axis xyz="0 0 1"/>
    <limit effort="500" velocity="20"/>
    <dynamics damping="0.003" friction="0.0"/>
  </joint>
  <link name="caster_rear_left_link">
    <visual>
      <origin rpy="1.5707963267948966 0 1.5707963267948966"/>
      <geometry>
        <mesh filename="meshes/murp/caster.stl"/>
      </geometry>
      <material name="darkgrey">
        <color rgba="0.3 0.3 0.3 1.0"/>
      </material>
    </visual>
    <collision>
      <origin rpy="1.5707963267948966 0 1.5707963267948966"/>
      <geometry>
        <mesh filename="meshes/murp/caster.stl"/>
      </geometry>
      <material name="darkgrey">
        <color rgba="0.3 0.3 0.3 1.0"/>
      </material>
    </collision>
    <inertial>
      <mass value="0.5"/>
      <inertia ixx="0.00033854166666666673" ixy="0" ixz="0" iyy="0.00033854166666666673" iyz="0" izz="0.0006250000000000001"/>
    </inertial>
  </link>
  <joint name="caster_rear_left_joint" type="continuous">
    <origin rpy="0 0 0" xyz="-0.035 0 -0.074"/>
    <parent link="caster_rear_left_fixed_link"/>
    <child link="caster_rear_left_link"/>
    <axis xyz="0 1 0"/>
    <limit effort="500" velocity="20"/>
    <dynamics damping="0.003" friction="0.0"/>
  </joint>
  <link name="bogie_right_link">
    <visual>
      <origin rpy="1.5707963267948966 0 0"/>
      <geometry>
        <cylinder length="0.0225" radius="0.015"/>
      </geometry>
      <material name="darkgrey">
        <color rgba="0.3 0.3 0.3 1.0"/>
      </material>
    </visual>
    <inertial>
      <mass value="3"/>
      <inertia ixx="0.025656250000000002" ixy="0" ixz="0" iyy="0.0257" iyz="0" izz="0.00015625"/>
    </inertial>
  </link>
  <joint name="bogie_right_joint" type="revolute">
    <origin xyz="-0.18 -0.25 0.075"/>
    <parent link="base_link"/>
    <child link="bogie_right_link"/>
    <axis xyz="0 1 0"/>
    <limit effort="500" lower="-0.16" upper="0.18" velocity="20"/>
    <dynamics damping="0.003" friction="0.0"/>
  </joint>
  <link name="r_wheel_link">
    <visual>
      <origin rpy="0 0 0"/>
      <geometry>
        <mesh filename="meshes/murp/wheel.stl"/>
      </geometry>
      <material name="darkgrey">
        <color rgba="0.3 0.3 0.3 1.0"/>
      </material>
    </visual>
    <collision>
      <origin rpy="0 0 0"/>
      <geometry>
        <mesh filename="tmr_description/meshes/collision/wheel_simplified.stl"/>
      </geometry>
    </collision>
    <inertial>
      <mass value="1"/>
      <inertia ixx="0.0041333333333333335" ixy="0" ixz="0" iyy="0.0041333333333333335" iyz="0" izz="0.0072"/>
    </inertial>
  </link>
  <joint name="r_wheel_joint" type="continuous">
    <origin xyz="0.18 -0.015 0.045"/>
    <parent link="bogie_right_link"/>
    <child link="r_wheel_link"/>
    <axis xyz="0 1 0"/>
    <limit effort="25" velocity="20"/>
  </joint>
  <link name="caster_rear_right_fixed_link">
    <visual>
      <origin xyz="0 0 -0.0015"/>
      <geometry>
        <box size="0.04 0.03 0.003"/>
      </geometry>
      <material name="darkgrey">
        <color rgba="0.3 0.3 0.3 1.0"/>
      </material>
    </visual>
    <inertial>
      <mass value="0.5"/>
      <inertia ixx="3.7875e-05" ixy="0" ixz="0" iyy="6.704166666666667e-05" iyz="0" izz="0.00010416666666666666"/>
    </inertial>
  </link>
  <joint name="caster_rear_right_steering_joint" type="continuous">
    <origin xyz="-0.13 -0.01 0.049"/>
    <parent link="bogie_right_link"/>
    <child link="caster_rear_right_fixed_link"/>
    <axis xyz="0 0 1"/>
    <limit effort="500" velocity="20"/>
    <dynamics damping="0.003" friction="0.0"/>
  </joint>
  <link name="caster_rear_right_link">
    <visual>
      <origin rpy="1.5707963267948966 0 1.5707963267948966"/>
      <geometry>
        <mesh filename="meshes/murp/caster.stl"/>
      </geometry>
      <material name="darkgrey">
        <color rgba="0.3 0.3 0.3 1.0"/>
      </material>
    </visual>
    <collision>
      <origin rpy="1.5707963267948966 0 1.5707963267948966"/>
      <geometry>
        <mesh filename="meshes/murp/caster.stl"/>
      </geometry>
      <material name="darkgrey">
        <color rgba="0.3 0.3 0.3 1.0"/>
      </material>
    </collision>
    <inertial>
      <mass value="0.5"/>
      <inertia ixx="0.00033854166666666673" ixy="0" ixz="0" iyy="0.00033854166666666673" iyz="0" izz="0.0006250000000000001"/>
    </inertial>
  </link>
  <joint name="caster_rear_right_joint" type="continuous">
    <origin rpy="0 0 0" xyz="-0.035 0 -0.074"/>
    <parent link="caster_rear_right_fixed_link"/>
    <child link="caster_rear_right_link"/>
    <axis xyz="0 1 0"/>
    <limit effort="500" velocity="20"/>
    <dynamics damping="0.003" friction="0.0"/>
  </joint>
</robot>
