<?xml version="1.0" ?>
<!-- =================================================================================== -->
<!-- |    This document was autogenerated by xacro from /workspaces/src/franka_description/robots/multi_arm/multi_arm.urdf.xacro | -->
<!-- |    EDITING THIS FILE BY HAND IS NOT RECOMMENDED                                 | -->
<!-- =================================================================================== -->
<robot name="murp">
  <link name="base">
  </link>
  <!-- ========================================= -->
  <!-- ||         Inertia Utilities           || -->
  <!-- ========================================= -->
  <link name="torso_link">
    <visual>
      <geometry>
        <mesh filename="../meshes/TMR/torso.stl"/>
      </geometry>
      <material name="white">
        <color rgba="1.0 1.0 1.0 1.0"/>
      </material>
    </visual>
    <collision>
      <geometry>
        <mesh filename="../meshes/TMR/torso.stl"/>
      </geometry>
    </collision>
    <inertial>
      <origin rpy="0 0 0" xyz="-0.374101 0.001522 0.120542"/>
      <mass value="75.711368"/>
      <inertia ixx="1.822241406454" ixy="0.009367998445" ixz="0.855091055826" iyx="0.009367998445" iyy="4.242134556907" iyz="-0.012022054390" izx="0.855091055826" izy="-0.012022054390" izz="4.568496104964"/>
    </inertial>
  </link>
  <joint name="torso_joint" type="fixed">
    <origin rpy="0 0 0" xyz="0.212 0 0.294"/>
    <parent link="base_link"/>
    <child link="torso_link"/>
  </joint>
  <joint name="left_base_joint" type="fixed">
    <parent link="torso_link"/>
    <child link="left_base"/>
    <origin rpy="-0.89334809 -0.17456074 -0.46334506" xyz="0.035 0.050681 0.356"/>
  </joint>
  <!-- safety_distance: Minimum safety distance in [m] by which the collision volumes are expanded and which is enforced during robot motions -->
  <!-- arm_id: Namespace of the robot arm. Serves to differentiate between arms in case of multiple instances. -->
  <!-- joint_limits: description of the joint limits that comes from a YAML file. Example definition: ${xacro.load_yaml('$(find franka_description)/robots/fr3/joint_limits.yaml')} -->
  <!-- kinematics: description of the kinematics that comes from a YAML file. Example definition: ${xacro.load_yaml('$(find franka_description)/robots/fr3/kinematics.yaml')} -->
  <!-- inertials: description of the inertials that comes from a YAML file. Example definition: ${xacro.load_yaml('$(find franka_description)/robots/fr3/inertials.yaml')} -->
  <!-- dynamics: description of the dynamics that comes from a YAML file. Example definition: ${xacro.load_yaml('$(find franka_description)/robots/fr3/dynamics.yaml')} -->
  <link name="left_base">
      </link>
  <joint name="left_fr3_left_base_joint" type="fixed">
    <parent link="left_base"/>
    <child link="left_fr3_link0"/>
    <origin rpy="0 0 0" xyz="0 0 0"/>
  </joint>
  <!-- sub-link defining detailed meshes for collision with environment -->
  <link name="left_fr3_link0">
    <visual name="left_fr3_link0_visual">
      <geometry>
        <mesh filename="meshes/TMR/link0.stl"/>
      </geometry>
    </visual>
    <collision name="left_fr3_link0_collision">
      <geometry>
        <mesh filename="meshes/TMR/link0.stl"/>
      </geometry>
    </collision>
    <inertial>
      <origin rpy="0 0 0" xyz="-0.0172 0.0004 0.0745"/>
      <mass value="2.3966"/>
      <inertia ixx="0.009" ixy="0.0" ixz="0.002" iyy="0.0115" iyz="0.0" izz="0.0085"/>
    </inertial>
  </link>
  <!-- sub-link defining detailed meshes for collision with environment -->
  <link name="left_fr3_link1">
    <visual name="left_fr3_link1_visual">
      <geometry>
        <mesh filename="meshes/TMR/link1.stl"/>
      </geometry>
    </visual>
    <collision name="left_fr3_link1_collision">
      <geometry>
        <mesh filename="meshes/TMR/link1.stl"/>
      </geometry>
    </collision>
    <inertial>
      <origin rpy="0 0 0" xyz="0.0000004128 -0.0181251324 -0.0386035970"/>
      <mass value="2.9274653454"/>
      <inertia ixx="0.023927316485107913" ixy="1.3317903455714081e-05" ixz="-0.00011404774918616684" iyy="0.0224821613275756" iyz="-0.0019950320628240115" izz="0.006350098258530016"/>
    </inertial>
  </link>
  <joint name="left_fr3_joint1" type="revolute">
    <origin rpy="0 0 0" xyz="0 0 0.333"/>
    <parent link="left_fr3_link0"/>
    <child link="left_fr3_link1"/>
    <axis xyz="0 0 1"/>
    <limit effort="87.0" lower="-2.7437" upper="2.7437" velocity="2.62"/>
    <safety_controller k_position="100.0" k_velocity="40.0" soft_lower_limit="-2.7437" soft_upper_limit="2.7437"/>
    <dynamics D="1" K="7000" damping="0.003" friction="0.2" mu_coulomb="0" mu_viscous="16"/>
  </joint>
  <!-- sub-link defining detailed meshes for collision with environment -->
  <link name="left_fr3_link2">
    <visual name="left_fr3_link2_visual">
      <geometry>
        <mesh filename="meshes/TMR/link2.stl"/>
      </geometry>
    </visual>
    <collision name="left_fr3_link2_collision">
      <geometry>
        <mesh filename="meshes/TMR/link2.stl"/>
      </geometry>
    </collision>
    <inertial>
      <origin rpy="0 0 0" xyz="0.0031828864 -0.0743221644 0.0088146084"/>
      <mass value="2.9355370338"/>
      <inertia ixx="0.041938946257609425" ixy="0.00020257331521090626" ixz="0.004077784227179924" iyy="0.02514514885014724" iyz="-0.0042252158006570156" izz="0.06170214472888839"/>
    </inertial>
  </link>
  <joint name="left_fr3_joint2" type="revolute">
    <origin rpy="-1.570796326794897 0 0" xyz="0 0 0"/>
    <parent link="left_fr3_link1"/>
    <child link="left_fr3_link2"/>
    <axis xyz="0 0 1"/>
    <limit effort="87.0" lower="-1.7837" upper="1.7837" velocity="2.62"/>
    <safety_controller k_position="100.0" k_velocity="40.0" soft_lower_limit="-1.7837" soft_upper_limit="1.7837"/>
    <dynamics D="1" K="7000" damping="0.003" friction="0.2" mu_coulomb="0" mu_viscous="16"/>
  </joint>
  <!-- sub-link defining detailed meshes for collision with environment -->
  <link name="left_fr3_link3">
    <visual name="left_fr3_link3_visual">
      <geometry>
        <mesh filename="meshes/TMR/link3.stl"/>
      </geometry>
    </visual>
    <collision name="left_fr3_link3_collision">
      <geometry>
        <mesh filename="meshes/TMR/link3.stl"/>
      </geometry>
    </collision>
    <inertial>
      <origin rpy="0 0 0" xyz="0.0407015686 -0.0048200565 -0.0289730823"/>
      <mass value="2.2449013699"/>
      <inertia ixx="0.02410142547240885" ixy="0.002404694559042109" ixz="-0.002856269270114313" iyy="0.01974053266708178" iyz="-0.002104212683891874" izz="0.019044494482244823"/>
    </inertial>
  </link>
  <joint name="left_fr3_joint3" type="revolute">
    <origin rpy="1.570796326794897 0 0" xyz="0 -0.316 0"/>
    <parent link="left_fr3_link2"/>
    <child link="left_fr3_link3"/>
    <axis xyz="0 0 1"/>
    <limit effort="87.0" lower="-2.9007" upper="2.9007" velocity="2.62"/>
    <safety_controller k_position="100.0" k_velocity="40.0" soft_lower_limit="-2.9007" soft_upper_limit="2.9007"/>
    <dynamics D="1" K="7000" damping="0.003" friction="0.2" mu_coulomb="0" mu_viscous="16"/>
  </joint>
  <!-- sub-link defining detailed meshes for collision with environment -->
  <link name="left_fr3_link4">
    <visual name="left_fr3_link4_visual">
      <geometry>
        <mesh filename="meshes/TMR/link4.stl"/>
      </geometry>
    </visual>
    <collision name="left_fr3_link4_collision">
      <geometry>
        <mesh filename="meshes/TMR/link4.stl"/>
      </geometry>
    </collision>
    <inertial>
      <origin rpy="0 0 0" xyz="-0.0459100965 0.0630492960 -0.0085187868"/>
      <mass value="2.6155955791"/>
      <inertia ixx="0.03452998321913202" ixy="0.01322552265982813" ixz="0.01015142998484113" iyy="0.028881621933049058" iyz="-0.0009762833870704552" izz="0.04125471171146641"/>
    </inertial>
  </link>
  <joint name="left_fr3_joint4" type="revolute">
    <origin rpy="1.570796326794897 0 0" xyz="0.0825 0 0"/>
    <parent link="left_fr3_link3"/>
    <child link="left_fr3_link4"/>
    <axis xyz="0 0 1"/>
    <limit effort="87.0" lower="-3.0421" upper="-0.1518" velocity="2.62"/>
    <safety_controller k_position="100.0" k_velocity="40.0" soft_lower_limit="-3.0421" soft_upper_limit="-0.1518"/>
    <dynamics D="1" K="7000" damping="0.003" friction="0.2" mu_coulomb="0" mu_viscous="16"/>
  </joint>
  <!-- sub-link defining detailed meshes for collision with environment -->
  <link name="left_fr3_link5">
    <visual name="left_fr3_link5_visual">
      <geometry>
        <mesh filename="meshes/TMR/link5.stl"/>
      </geometry>
    </visual>
    <collision name="left_fr3_link5_collision">
      <geometry>
        <mesh filename="meshes/TMR/link5.stl"/>
      </geometry>
    </collision>
    <inertial>
      <origin rpy="0 0 0" xyz="-0.0016039605 0.0292536262 -0.0972965990"/>
      <mass value="2.3271207594"/>
      <inertia ixx="0.051610278463662895" ixy="-0.005715173387783472" ixz="-0.0035673167625872135" iyy="0.04787729713371481" iyz="0.010673985108535986" izz="0.016423625579357254"/>
    </inertial>
  </link>
  <joint name="left_fr3_joint5" type="revolute">
    <origin rpy="-1.570796326794897 0 0" xyz="-0.0825 0.384 0"/>
    <parent link="left_fr3_link4"/>
    <child link="left_fr3_link5"/>
    <axis xyz="0 0 1"/>
    <limit effort="12.0" lower="-2.8065" upper="2.8065" velocity="5.26"/>
    <safety_controller k_position="100.0" k_velocity="40.0" soft_lower_limit="-2.8065" soft_upper_limit="2.8065"/>
    <dynamics D="1" K="7000" damping="0.003" friction="0.2" mu_coulomb="0" mu_viscous="16"/>
  </joint>
  <!-- sub-link defining detailed meshes for collision with environment -->
  <link name="left_fr3_link6">
    <visual name="left_fr3_link6_visual">
      <geometry>
        <mesh filename="meshes/TMR/link6.stl"/>
      </geometry>
    </visual>
    <collision name="left_fr3_link6_collision">
      <geometry>
        <mesh filename="meshes/TMR/link6.stl"/>
      </geometry>
    </collision>
    <inertial>
      <origin rpy="0 0 0" xyz="0.0597131221 -0.0410294666 -0.0101692726"/>
      <mass value="1.8170376524"/>
      <inertia ixx="0.005412333594383447" ixy="0.006193456360285834" ixz="0.0014219289306117652" iyy="0.014058329545509979" iyz="-0.0013140753741120031" izz="0.016080817924212554"/>
    </inertial>
  </link>
  <joint name="left_fr3_joint6" type="revolute">
    <origin rpy="1.570796326794897 0 0" xyz="0 0 0"/>
    <parent link="left_fr3_link5"/>
    <child link="left_fr3_link6"/>
    <axis xyz="0 0 1"/>
    <limit effort="12.0" lower="0.5445" upper="4.5169" velocity="4.18"/>
    <safety_controller k_position="100.0" k_velocity="40.0" soft_lower_limit="0.5445" soft_upper_limit="4.5169"/>
    <dynamics D="1" K="7000" damping="0.003" friction="0.2" mu_coulomb="0" mu_viscous="16"/>
  </joint>
  <!-- sub-link defining detailed meshes for collision with environment -->
  <link name="left_fr3_link7">
    <visual name="left_fr3_link7_visual">
      <geometry>
        <mesh filename="meshes/TMR/link7.stl"/>
      </geometry>
    </visual>
    <collision name="left_fr3_link7_collision">
      <geometry>
        <mesh filename="meshes/TMR/link7.stl"/>
      </geometry>
    </collision>
    <inertial>
      <origin rpy="0 0 0" xyz="0.0045225817 0.0086261921 -0.0161633251"/>
      <mass value="0.6271432862"/>
      <inertia ixx="0.00021092389150104718" ixy="-2.433299114461931e-05" ixz="4.564480393778983e-05" iyy="0.00017718568002411474" iyz="8.744070223226438e-05" izz="5.993190599659971e-05"/>
    </inertial>
  </link>
  <joint name="left_fr3_joint7" type="revolute">
    <origin rpy="1.570796326794897 0 0" xyz="0.088 0 0"/>
    <parent link="left_fr3_link6"/>
    <child link="left_fr3_link7"/>
    <axis xyz="0 0 1"/>
    <limit effort="12.0" lower="-3.0159" upper="3.0159" velocity="5.26"/>
    <safety_controller k_position="100.0" k_velocity="40.0" soft_lower_limit="-3.0159" soft_upper_limit="3.0159"/>
    <dynamics D="1" K="7000" damping="0.003" friction="0.2" mu_coulomb="0" mu_viscous="16"/>
  </joint>
  <link name="left_fr3_link8"/>
  <joint name="left_fr3_joint8" type="fixed">
    <origin rpy="0 0 0" xyz="0 0 0.107"/>
    <parent link="left_fr3_link7"/>
    <child link="left_fr3_link8"/>
  </joint>
  <joint name="right_base_joint" type="fixed">
    <parent link="torso_link"/>
    <child link="right_base"/>
    <origin rpy="0.89334809 -0.17456074 0.46334506" xyz="0.035 -0.050681 0.356"/>
  </joint>
  <!-- safety_distance: Minimum safety distance in [m] by which the collision volumes are expanded and which is enforced during robot motions -->
  <!-- arm_id: Namespace of the robot arm. Serves to differentiate between arms in case of multiple instances. -->
  <!-- joint_limits: description of the joint limits that comes from a YAML file. Example definition: ${xacro.load_yaml('$(find franka_description)/robots/fr3/joint_limits.yaml')} -->
  <!-- kinematics: description of the kinematics that comes from a YAML file. Example definition: ${xacro.load_yaml('$(find franka_description)/robots/fr3/kinematics.yaml')} -->
  <!-- inertials: description of the inertials that comes from a YAML file. Example definition: ${xacro.load_yaml('$(find franka_description)/robots/fr3/inertials.yaml')} -->
  <!-- dynamics: description of the dynamics that comes from a YAML file. Example definition: ${xacro.load_yaml('$(find franka_description)/robots/fr3/dynamics.yaml')} -->
  <link name="right_base">
      </link>
  <joint name="right_fr3_right_base_joint" type="fixed">
    <parent link="right_base"/>
    <child link="right_fr3_link0"/>
    <origin rpy="0 0 0" xyz="0 0 0"/>
  </joint>
  <!-- sub-link defining detailed meshes for collision with environment -->
  <link name="right_fr3_link0">
    <visual name="right_fr3_link0_visual">
      <geometry>
        <mesh filename="meshes/TMR/link0.stl"/>
      </geometry>
    </visual>
    <collision name="right_fr3_link0_collision">
      <geometry>
        <mesh filename="meshes/TMR/link0.stl"/>
      </geometry>
    </collision>
    <inertial>
      <origin rpy="0 0 0" xyz="-0.0172 0.0004 0.0745"/>
      <mass value="2.3966"/>
      <inertia ixx="0.009" ixy="0.0" ixz="0.002" iyy="0.0115" iyz="0.0" izz="0.0085"/>
    </inertial>
  </link>
  <!-- sub-link defining detailed meshes for collision with environment -->
  <link name="right_fr3_link1">
    <visual name="right_fr3_link1_visual">
      <geometry>
        <mesh filename="meshes/TMR/link1.stl"/>
      </geometry>
    </visual>
    <collision name="right_fr3_link1_collision">
      <geometry>
        <mesh filename="meshes/TMR/link1.stl"/>
      </geometry>
    </collision>
    <inertial>
      <origin rpy="0 0 0" xyz="0.0000004128 -0.0181251324 -0.0386035970"/>
      <mass value="2.9274653454"/>
      <inertia ixx="0.023927316485107913" ixy="1.3317903455714081e-05" ixz="-0.00011404774918616684" iyy="0.0224821613275756" iyz="-0.0019950320628240115" izz="0.006350098258530016"/>
    </inertial>
  </link>
  <joint name="right_fr3_joint1" type="revolute">
    <origin rpy="0 0 0" xyz="0 0 0.333"/>
    <parent link="right_fr3_link0"/>
    <child link="right_fr3_link1"/>
    <axis xyz="0 0 1"/>
    <limit effort="87.0" lower="-2.7437" upper="2.7437" velocity="2.62"/>
    <safety_controller k_position="100.0" k_velocity="40.0" soft_lower_limit="-2.7437" soft_upper_limit="2.7437"/>
    <dynamics D="1" K="7000" damping="0.003" friction="0.2" mu_coulomb="0" mu_viscous="16"/>
  </joint>
  <!-- sub-link defining detailed meshes for collision with environment -->
  <link name="right_fr3_link2">
    <visual name="right_fr3_link2_visual">
      <geometry>
        <mesh filename="meshes/TMR/link2.stl"/>
      </geometry>
    </visual>
    <collision name="right_fr3_link2_collision">
      <geometry>
        <mesh filename="meshes/TMR/link2.stl"/>
      </geometry>
    </collision>
    <inertial>
      <origin rpy="0 0 0" xyz="0.0031828864 -0.0743221644 0.0088146084"/>
      <mass value="2.9355370338"/>
      <inertia ixx="0.041938946257609425" ixy="0.00020257331521090626" ixz="0.004077784227179924" iyy="0.02514514885014724" iyz="-0.0042252158006570156" izz="0.06170214472888839"/>
    </inertial>
  </link>
  <joint name="right_fr3_joint2" type="revolute">
    <origin rpy="-1.570796326794897 0 0" xyz="0 0 0"/>
    <parent link="right_fr3_link1"/>
    <child link="right_fr3_link2"/>
    <axis xyz="0 0 1"/>
    <limit effort="87.0" lower="-1.7837" upper="1.7837" velocity="2.62"/>
    <safety_controller k_position="100.0" k_velocity="40.0" soft_lower_limit="-1.7837" soft_upper_limit="1.7837"/>
    <dynamics D="1" K="7000" damping="0.003" friction="0.2" mu_coulomb="0" mu_viscous="16"/>
  </joint>
  <!-- sub-link defining detailed meshes for collision with environment -->
  <link name="right_fr3_link3">
    <visual name="right_fr3_link3_visual">
      <geometry>
        <mesh filename="meshes/TMR/link3.stl"/>
      </geometry>
    </visual>
    <collision name="right_fr3_link3_collision">
      <geometry>
        <mesh filename="meshes/TMR/link3.stl"/>
      </geometry>
    </collision>
    <inertial>
      <origin rpy="0 0 0" xyz="0.0407015686 -0.0048200565 -0.0289730823"/>
      <mass value="2.2449013699"/>
      <inertia ixx="0.02410142547240885" ixy="0.002404694559042109" ixz="-0.002856269270114313" iyy="0.01974053266708178" iyz="-0.002104212683891874" izz="0.019044494482244823"/>
    </inertial>
  </link>
  <joint name="right_fr3_joint3" type="revolute">
    <origin rpy="1.570796326794897 0 0" xyz="0 -0.316 0"/>
    <parent link="right_fr3_link2"/>
    <child link="right_fr3_link3"/>
    <axis xyz="0 0 1"/>
    <limit effort="87.0" lower="-2.9007" upper="2.9007" velocity="2.62"/>
    <safety_controller k_position="100.0" k_velocity="40.0" soft_lower_limit="-2.9007" soft_upper_limit="2.9007"/>
    <dynamics D="1" K="7000" damping="0.003" friction="0.2" mu_coulomb="0" mu_viscous="16"/>
  </joint>
  <!-- sub-link defining detailed meshes for collision with environment -->
  <link name="right_fr3_link4">
    <visual name="right_fr3_link4_visual">
      <geometry>
        <mesh filename="meshes/TMR/link4.stl"/>
      </geometry>
    </visual>
    <collision name="right_fr3_link4_collision">
      <geometry>
        <mesh filename="meshes/TMR/link4.stl"/>
      </geometry>
    </collision>
    <inertial>
      <origin rpy="0 0 0" xyz="-0.0459100965 0.0630492960 -0.0085187868"/>
      <mass value="2.6155955791"/>
      <inertia ixx="0.03452998321913202" ixy="0.01322552265982813" ixz="0.01015142998484113" iyy="0.028881621933049058" iyz="-0.0009762833870704552" izz="0.04125471171146641"/>
    </inertial>
  </link>
  <joint name="right_fr3_joint4" type="revolute">
    <origin rpy="1.570796326794897 0 0" xyz="0.0825 0 0"/>
    <parent link="right_fr3_link3"/>
    <child link="right_fr3_link4"/>
    <axis xyz="0 0 1"/>
    <limit effort="87.0" lower="-3.0421" upper="-0.1518" velocity="2.62"/>
    <safety_controller k_position="100.0" k_velocity="40.0" soft_lower_limit="-3.0421" soft_upper_limit="-0.1518"/>
    <dynamics D="1" K="7000" damping="0.003" friction="0.2" mu_coulomb="0" mu_viscous="16"/>
  </joint>
  <!-- sub-link defining detailed meshes for collision with environment -->
  <link name="right_fr3_link5">
    <visual name="right_fr3_link5_visual">
      <geometry>
        <mesh filename="meshes/TMR/link5.stl"/>
      </geometry>
    </visual>
    <collision name="right_fr3_link5_collision">
      <geometry>
        <mesh filename="meshes/TMR/link5.stl"/>
      </geometry>
    </collision>
    <inertial>
      <origin rpy="0 0 0" xyz="-0.0016039605 0.0292536262 -0.0972965990"/>
      <mass value="2.3271207594"/>
      <inertia ixx="0.051610278463662895" ixy="-0.005715173387783472" ixz="-0.0035673167625872135" iyy="0.04787729713371481" iyz="0.010673985108535986" izz="0.016423625579357254"/>
    </inertial>
  </link>
  <joint name="right_fr3_joint5" type="revolute">
    <origin rpy="-1.570796326794897 0 0" xyz="-0.0825 0.384 0"/>
    <parent link="right_fr3_link4"/>
    <child link="right_fr3_link5"/>
    <axis xyz="0 0 1"/>
    <limit effort="12.0" lower="-2.8065" upper="2.8065" velocity="5.26"/>
    <safety_controller k_position="100.0" k_velocity="40.0" soft_lower_limit="-2.8065" soft_upper_limit="2.8065"/>
    <dynamics D="1" K="7000" damping="0.003" friction="0.2" mu_coulomb="0" mu_viscous="16"/>
  </joint>
  <!-- sub-link defining detailed meshes for collision with environment -->
  <link name="right_fr3_link6">
    <visual name="right_fr3_link6_visual">
      <geometry>
        <mesh filename="meshes/TMR/link6.stl"/>
      </geometry>
    </visual>
    <collision name="right_fr3_link6_collision">
      <geometry>
        <mesh filename="meshes/TMR/link6.stl"/>
      </geometry>
    </collision>
    <inertial>
      <origin rpy="0 0 0" xyz="0.0597131221 -0.0410294666 -0.0101692726"/>
      <mass value="1.8170376524"/>
      <inertia ixx="0.005412333594383447" ixy="0.006193456360285834" ixz="0.0014219289306117652" iyy="0.014058329545509979" iyz="-0.0013140753741120031" izz="0.016080817924212554"/>
    </inertial>
  </link>
  <joint name="right_fr3_joint6" type="revolute">
    <origin rpy="1.570796326794897 0 0" xyz="0 0 0"/>
    <parent link="right_fr3_link5"/>
    <child link="right_fr3_link6"/>
    <axis xyz="0 0 1"/>
    <limit effort="12.0" lower="0.5445" upper="4.5169" velocity="4.18"/>
    <safety_controller k_position="100.0" k_velocity="40.0" soft_lower_limit="0.5445" soft_upper_limit="4.5169"/>
    <dynamics D="1" K="7000" damping="0.003" friction="0.2" mu_coulomb="0" mu_viscous="16"/>
  </joint>
  <!-- sub-link defining detailed meshes for collision with environment -->
  <link name="right_fr3_link7">
    <visual name="right_fr3_link7_visual">
      <geometry>
        <mesh filename="meshes/TMR/link7.stl"/>
      </geometry>
    </visual>
    <collision name="right_fr3_link7_collision">
      <geometry>
        <mesh filename="meshes/TMR/link7.stl"/>
      </geometry>
    </collision>
    <inertial>
      <origin rpy="0 0 0" xyz="0.0045225817 0.0086261921 -0.0161633251"/>
      <mass value="0.6271432862"/>
      <inertia ixx="0.00021092389150104718" ixy="-2.433299114461931e-05" ixz="4.564480393778983e-05" iyy="0.00017718568002411474" iyz="8.744070223226438e-05" izz="5.993190599659971e-05"/>
    </inertial>
  </link>
  <joint name="right_fr3_joint7" type="revolute">
    <origin rpy="1.570796326794897 0 0" xyz="0.088 0 0"/>
    <parent link="right_fr3_link6"/>
    <child link="right_fr3_link7"/>
    <axis xyz="0 0 1"/>
    <limit effort="12.0" lower="-3.0159" upper="3.0159" velocity="5.26"/>
    <safety_controller k_position="100.0" k_velocity="40.0" soft_lower_limit="-3.0159" soft_upper_limit="3.0159"/>
    <dynamics D="1" K="7000" damping="0.003" friction="0.2" mu_coulomb="0" mu_viscous="16"/>
  </joint>
  <link name="right_fr3_link8"/>
  <joint name="right_fr3_joint8" type="fixed">
    <origin rpy="0 0 0" xyz="0 0 0.107"/>
    <parent link="right_fr3_link7"/>
    <child link="right_fr3_link8"/>
  </joint>
  <joint name="platform_base" type="fixed">
    <parent link="base"/>
    <child link="base_link"/>
    <origin rpy="0 0 0" xyz="0 0 0"/>
  </joint>
  <!-- ========================================= -->
  <!-- ||         Inertia Utilities           || -->
  <!-- ========================================= -->
  <!-- ========================================= -->
  <!-- ||         Inertia Utilities           || -->
  <!-- ========================================= -->
  <!-- ========================================= -->
  <!-- ||         Inertia Utilities           || -->
  <!-- ========================================= -->
  <!-- ========================================= -->
  <!-- ||         Inertia Utilities           || -->
  <!-- ========================================= -->
  <material name="aluminum">
    <color rgba="0.5 0.5 0.5 1"/>
  </material>
  <material name="plastic">
    <color rgba="0.1 0.1 0.1 1"/>
  </material>
  <!-- Main Platform Chassis -->
  <link name="base_link">
    <visual>
      <origin rpy="0 0 3.141592653589793" xyz="0 0 0"/>
      <geometry>
        <mesh filename="meshes/TMR/tmr_base.stl"/>
      </geometry>
      <material name="white">
        <color rgba="1.0 1.0 1.0 1.0"/>
      </material>
    </visual>
    <collision>
      <origin rpy="0 0 3.141592653589793" xyz="0 0 0"/>
      <geometry>
        <mesh filename="meshes/TMR/tmr_base.stl"/>
      </geometry>
    </collision>
  </link>
  <link name="base_inertia">
    <inertial>
      <mass value="75"/>
      <inertia ixx="4.540225" ixy="0" ixz="0" iyy="6.06640625" iyz="0" izz="2.6066312499999995"/>
    </inertial>
  </link>
  <joint name="base_inertia_joint" type="fixed">
    <parent link="base_link"/>
    <child link="base_inertia"/>
  </joint>
  <link name="caster_front_left_fixed_link">
    <visual>
      <origin xyz="0 0 -0.0015"/>
      <geometry>
        <box size="0.04 0.03 0.003"/>
      </geometry>
      <material name="darkgrey">
        <color rgba="0.3 0.3 0.3 1.0"/>
      </material>
    </visual>
    <inertial>
      <mass value="0.5"/>
      <inertia ixx="3.7875e-05" ixy="0" ixz="0" iyy="6.704166666666667e-05" iyz="0" izz="0.00010416666666666666"/>
    </inertial>
  </link>
  <joint name="caster_front_left_steering_joint" type="continuous">
    <origin xyz="0.33 0.26 0.124"/>
    <parent link="base_link"/>
    <child link="caster_front_left_fixed_link"/>
    <axis xyz="0 0 1"/>
    <limit effort="500" velocity="20"/>
    <dynamics damping="0.003" friction="0.0"/>
  </joint>
  <link name="caster_front_left_link">
    <visual>
      <origin rpy="1.5707963267948966 0 1.5707963267948966"/>
      <geometry>
        <mesh filename="meshes/TMR/caster.stl"/>
      </geometry>
      <material name="darkgrey">
        <color rgba="0.3 0.3 0.3 1.0"/>
      </material>
    </visual>
    <collision>
      <origin rpy="1.5707963267948966 0 1.5707963267948966"/>
      <geometry>
        <mesh filename="meshes/TMR/caster.stl"/>
      </geometry>
      <material name="darkgrey">
        <color rgba="0.3 0.3 0.3 1.0"/>
      </material>
    </collision>
    <inertial>
      <mass value="0.5"/>
      <inertia ixx="0.00033854166666666673" ixy="0" ixz="0" iyy="0.00033854166666666673" iyz="0" izz="0.0006250000000000001"/>
    </inertial>
  </link>
  <joint name="caster_front_left_joint" type="continuous">
    <origin rpy="0 0 0" xyz="-0.035 0 -0.074"/>
    <parent link="caster_front_left_fixed_link"/>
    <child link="caster_front_left_link"/>
    <axis xyz="0 1 0"/>
    <limit effort="500" velocity="20"/>
    <dynamics damping="0.003" friction="0.0"/>
  </joint>
  <link name="caster_front_right_fixed_link">
    <visual>
      <origin xyz="0 0 -0.0015"/>
      <geometry>
        <box size="0.04 0.03 0.003"/>
      </geometry>
      <material name="darkgrey">
        <color rgba="0.3 0.3 0.3 1.0"/>
      </material>
    </visual>
    <inertial>
      <mass value="0.5"/>
      <inertia ixx="3.7875e-05" ixy="0" ixz="0" iyy="6.704166666666667e-05" iyz="0" izz="0.00010416666666666666"/>
    </inertial>
  </link>
  <joint name="caster_front_right_steering_joint" type="continuous">
    <origin xyz="0.33 -0.26 0.124"/>
    <parent link="base_link"/>
    <child link="caster_front_right_fixed_link"/>
    <axis xyz="0 0 1"/>
    <limit effort="500" velocity="20"/>
    <dynamics damping="0.003" friction="0.0"/>
  </joint>
  <link name="caster_front_right_link">
    <visual>
      <origin rpy="1.5707963267948966 0 1.5707963267948966"/>
      <geometry>
        <mesh filename="meshes/TMR/caster.stl"/>
      </geometry>
      <material name="darkgrey">
        <color rgba="0.3 0.3 0.3 1.0"/>
      </material>
    </visual>
    <collision>
      <origin rpy="1.5707963267948966 0 1.5707963267948966"/>
      <geometry>
        <mesh filename="meshes/TMR/caster.stl"/>
      </geometry>
      <material name="darkgrey">
        <color rgba="0.3 0.3 0.3 1.0"/>
      </material>
    </collision>
    <inertial>
      <mass value="0.5"/>
      <inertia ixx="0.00033854166666666673" ixy="0" ixz="0" iyy="0.00033854166666666673" iyz="0" izz="0.0006250000000000001"/>
    </inertial>
  </link>
  <joint name="caster_front_right_joint" type="continuous">
    <origin rpy="0 0 0" xyz="-0.035 0 -0.074"/>
    <parent link="caster_front_right_fixed_link"/>
    <child link="caster_front_right_link"/>
    <axis xyz="0 1 0"/>
    <limit effort="500" velocity="20"/>
    <dynamics damping="0.003" friction="0.0"/>
  </joint>
  <link name="bogie_left_link">
    <visual>
      <origin rpy="1.5707963267948966 0 0"/>
      <geometry>
        <cylinder length="0.0225" radius="0.015"/>
      </geometry>
      <material name="darkgrey">
        <color rgba="0.3 0.3 0.3 1.0"/>
      </material>
    </visual>
    <inertial>
      <mass value="3"/>
      <inertia ixx="0.025656250000000002" ixy="0" ixz="0" iyy="0.0257" iyz="0" izz="0.00015625"/>
    </inertial>
  </link>
  <joint name="bogie_left_joint" type="revolute">
    <origin xyz="-0.18 0.25 0.075"/>
    <parent link="base_link"/>
    <child link="bogie_left_link"/>
    <axis xyz="0 1 0"/>
    <limit effort="500" lower="-0.16" upper="0.18" velocity="20"/>
    <dynamics damping="0.003" friction="0.0"/>
  </joint>
  <link name="l_wheel_link">
    <visual>
      <origin rpy="3.141592653589793 0 0"/>
      <geometry>
        <mesh filename="meshes/TMR/wheel.stl"/>
      </geometry>
      <material name="darkgrey">
        <color rgba="0.3 0.3 0.3 1.0"/>
      </material>
    </visual>
    <collision>
      <origin rpy="3.141592653589793 0 0"/>
      <geometry>
        <mesh filename="meshes/TMR/wheel.stl"/>
      </geometry>
    </collision>
    <inertial>
      <mass value="1"/>
      <inertia ixx="0.0041333333333333335" ixy="0" ixz="0" iyy="0.0041333333333333335" iyz="0" izz="0.0072"/>
    </inertial>
  </link>
  <joint name="l_wheel_joint" type="continuous">
    <origin xyz="0.18 0.015 0.045"/>
    <parent link="bogie_left_link"/>
    <child link="l_wheel_link"/>
    <axis xyz="0 1 0"/>
    <limit effort="25" velocity="20"/>
  </joint>
  <link name="caster_rear_left_fixed_link">
    <visual>
      <origin xyz="0 0 -0.0015"/>
      <geometry>
        <box size="0.04 0.03 0.003"/>
      </geometry>
      <material name="darkgrey">
        <color rgba="0.3 0.3 0.3 1.0"/>
      </material>
    </visual>
    <inertial>
      <mass value="0.5"/>
      <inertia ixx="3.7875e-05" ixy="0" ixz="0" iyy="6.704166666666667e-05" iyz="0" izz="0.00010416666666666666"/>
    </inertial>
  </link>
  <joint name="caster_rear_left_steering_joint" type="continuous">
    <origin xyz="-0.13 0.01 0.049"/>
    <parent link="bogie_left_link"/>
    <child link="caster_rear_left_fixed_link"/>
    <axis xyz="0 0 1"/>
    <limit effort="500" velocity="20"/>
    <dynamics damping="0.003" friction="0.0"/>
  </joint>
  <link name="caster_rear_left_link">
    <visual>
      <origin rpy="1.5707963267948966 0 1.5707963267948966"/>
      <geometry>
        <mesh filename="meshes/TMR/caster.stl"/>
      </geometry>
      <material name="darkgrey">
        <color rgba="0.3 0.3 0.3 1.0"/>
      </material>
    </visual>
    <collision>
      <origin rpy="1.5707963267948966 0 1.5707963267948966"/>
      <geometry>
        <mesh filename="meshes/TMR/caster.stl"/>
      </geometry>
      <material name="darkgrey">
        <color rgba="0.3 0.3 0.3 1.0"/>
      </material>
    </collision>
    <inertial>
      <mass value="0.5"/>
      <inertia ixx="0.00033854166666666673" ixy="0" ixz="0" iyy="0.00033854166666666673" iyz="0" izz="0.0006250000000000001"/>
    </inertial>
  </link>
  <joint name="caster_rear_left_joint" type="continuous">
    <origin rpy="0 0 0" xyz="-0.035 0 -0.074"/>
    <parent link="caster_rear_left_fixed_link"/>
    <child link="caster_rear_left_link"/>
    <axis xyz="0 1 0"/>
    <limit effort="500" velocity="20"/>
    <dynamics damping="0.003" friction="0.0"/>
  </joint>
  <link name="bogie_right_link">
    <visual>
      <origin rpy="1.5707963267948966 0 0"/>
      <geometry>
        <cylinder length="0.0225" radius="0.015"/>
      </geometry>
      <material name="darkgrey">
        <color rgba="0.3 0.3 0.3 1.0"/>
      </material>
    </visual>
    <inertial>
      <mass value="3"/>
      <inertia ixx="0.025656250000000002" ixy="0" ixz="0" iyy="0.0257" iyz="0" izz="0.00015625"/>
    </inertial>
  </link>
  <joint name="bogie_right_joint" type="revolute">
    <origin xyz="-0.18 -0.25 0.075"/>
    <parent link="base_link"/>
    <child link="bogie_right_link"/>
    <axis xyz="0 1 0"/>
    <limit effort="500" lower="-0.16" upper="0.18" velocity="20"/>
    <dynamics damping="0.003" friction="0.0"/>
  </joint>
  <link name="r_wheel_link">
    <visual>
      <origin rpy="0 0 0"/>
      <geometry>
        <mesh filename="meshes/TMR/wheel.stl"/>
      </geometry>
      <material name="darkgrey">
        <color rgba="0.3 0.3 0.3 1.0"/>
      </material>
    </visual>
    <collision>
      <origin rpy="0 0 0"/>
      <geometry>
        <mesh filename="meshes/TMR/wheel.stl"/>
      </geometry>
    </collision>
    <inertial>
      <mass value="1"/>
      <inertia ixx="0.0041333333333333335" ixy="0" ixz="0" iyy="0.0041333333333333335" iyz="0" izz="0.0072"/>
    </inertial>
  </link>
  <joint name="r_wheel_joint" type="continuous">
    <origin xyz="0.18 -0.015 0.045"/>
    <parent link="bogie_right_link"/>
    <child link="r_wheel_link"/>
    <axis xyz="0 1 0"/>
    <limit effort="25" velocity="20"/>
  </joint>
  <link name="caster_rear_right_fixed_link">
    <visual>
      <origin xyz="0 0 -0.0015"/>
      <geometry>
        <box size="0.04 0.03 0.003"/>
      </geometry>
      <material name="darkgrey">
        <color rgba="0.3 0.3 0.3 1.0"/>
      </material>
    </visual>
    <inertial>
      <mass value="0.5"/>
      <inertia ixx="3.7875e-05" ixy="0" ixz="0" iyy="6.704166666666667e-05" iyz="0" izz="0.00010416666666666666"/>
    </inertial>
  </link>
  <joint name="caster_rear_right_steering_joint" type="continuous">
    <origin xyz="-0.13 -0.01 0.049"/>
    <parent link="bogie_right_link"/>
    <child link="caster_rear_right_fixed_link"/>
    <axis xyz="0 0 1"/>
    <limit effort="500" velocity="20"/>
    <dynamics damping="0.003" friction="0.0"/>
  </joint>
  <link name="caster_rear_right_link">
    <visual>
      <origin rpy="1.5707963267948966 0 1.5707963267948966"/>
      <geometry>
        <mesh filename="meshes/TMR/caster.stl"/>
      </geometry>
      <material name="darkgrey">
        <color rgba="0.3 0.3 0.3 1.0"/>
      </material>
    </visual>
    <collision>
      <origin rpy="1.5707963267948966 0 1.5707963267948966"/>
      <geometry>
        <mesh filename="meshes/TMR/caster.stl"/>
      </geometry>
      <material name="darkgrey">
        <color rgba="0.3 0.3 0.3 1.0"/>
      </material>
    </collision>
    <inertial>
      <mass value="0.5"/>
      <inertia ixx="0.00033854166666666673" ixy="0" ixz="0" iyy="0.00033854166666666673" iyz="0" izz="0.0006250000000000001"/>
    </inertial>
  </link>
  <joint name="caster_rear_right_joint" type="continuous">
    <origin rpy="0 0 0" xyz="-0.035 0 -0.074"/>
    <parent link="caster_rear_right_fixed_link"/>
    <child link="caster_rear_right_link"/>
    <axis xyz="0 1 0"/>
    <limit effort="500" velocity="20"/>
    <dynamics damping="0.003" friction="0.0"/>
  </joint>
</robot>