<mujoco model="murp">
  <compiler angle="radian"/>

  <asset>
    <mesh name="torso" file="meshes/TMR/torso.stl"/>
    <mesh name="link0" file="meshes/TMR/link0.stl"/>
    <mesh name="link1" file="meshes/TMR/link1.stl"/>
    <mesh name="link2" file="meshes/TMR/link2.stl"/>
    <mesh name="link3" file="meshes/TMR/link3.stl"/>
    <mesh name="link4" file="meshes/TMR/link4.stl"/>
    <mesh name="link5" file="meshes/TMR/link5.stl"/>
    <mesh name="link6" file="meshes/TMR/link6.stl"/>
    <mesh name="link7" file="meshes/TMR/link7.stl"/>
    <mesh name="tmr_base" file="meshes/TMR/tmr_base.stl"/>
    <mesh name="caster" file="meshes/TMR/caster.stl"/>
    <mesh name="wheel" file="meshes/TMR/wheel.stl"/>
  </asset>

  <worldbody>
    <geom pos="0 0 0" quat="0 0 0 1" type="mesh" rgba="1 1 1 1" mesh="tmr_base"/>
    <geom pos="0.212 0 0.294" quat="1 0 0 0" type="mesh" rgba="1 1 1 1" mesh="torso"/>
    <geom name="left_fr3_link0_collision" pos="0.247 0.050681 0.65" quat="0.865807 -0.436878 0.0222879 -0.242939" type="mesh" mesh="link0"/>
    <geom name="right_fr3_link0_collision" pos="0.247 -0.050681 0.65" quat="0.865807 0.436878 0.0222879 0.242939" type="mesh" mesh="link0"/>
    <body name="left_fr3_link1" pos="0.330538 0.298991 0.855555" quat="0.865807 -0.436878 0.0222879 -0.242939">
      <inertial pos="4.128e-07 -0.0181251 -0.0386036" quat="0.998098 -0.0605364 0.00380499 0.0110109" mass="2.92747" diaginertia="0.0239286 0.0227246 0.00610634"/>
      <joint name="left_fr3_joint1" pos="0 0 0" axis="0 0 1" range="-2.7437 2.7437" actuatorfrcrange="-87 87" damping="0.003" frictionloss="0.2"/>
      <geom name="left_fr3_link1_collision" type="mesh" mesh="link1"/>
      <body name="left_fr3_link2" quat="0.707107 -0.707107 0 0">
        <inertial pos="0.00318289 -0.0743222 0.00881461" quat="0.502599 0.584437 -0.465998 0.434366" mass="2.93554" diaginertia="0.0629567 0.0411924 0.0246371"/>
        <joint name="left_fr3_joint2" pos="0 0 0" axis="0 0 1" range="-1.7837 1.7837" actuatorfrcrange="-87 87" damping="0.003" frictionloss="0.2"/>
        <geom name="left_fr3_link2_collision" type="mesh" mesh="link2"/>
        <body name="left_fr3_link3" pos="0 -0.316 0" quat="0.707107 0.707107 0 0">
          <inertial pos="0.0407016 -0.00482006 -0.0289731" quat="0.921025 -0.244161 0.155272 0.260745" mass="2.2449" diaginertia="0.0267409 0.0189869 0.0171587"/>
          <joint name="left_fr3_joint3" pos="0 0 0" axis="0 0 1" range="-2.9007 2.9007" actuatorfrcrange="-87 87" damping="0.003" frictionloss="0.2"/>
          <geom name="left_fr3_link3_collision" type="mesh" mesh="link3"/>
          <body name="left_fr3_link4" pos="0.0825 0 0" quat="0.707107 0.707107 0 0">
            <inertial pos="-0.0459101 0.0630493 -0.00851879" quat="0.438018 0.803311 0.00937812 0.403414" mass="2.6156" diaginertia="0.05139 0.0372717 0.0160047"/>
            <joint name="left_fr3_joint4" pos="0 0 0" axis="0 0 1" range="-3.0421 -0.1518" actuatorfrcrange="-87 87" damping="0.003" frictionloss="0.2"/>
            <geom name="left_fr3_link4_collision" type="mesh" mesh="link4"/>
            <body name="left_fr3_link5" pos="-0.0825 0.384 0" quat="0.707107 -0.707107 0 0">
              <inertial pos="-0.00160396 0.0292536 -0.0972966" quat="0.919031 0.125604 0.0751531 -0.366003" mass="2.32712" diaginertia="0.0579335 0.0449144 0.0130634"/>
              <joint name="left_fr3_joint5" pos="0 0 0" axis="0 0 1" range="-2.8065 2.8065" actuatorfrcrange="-12 12" damping="0.003" frictionloss="0.2"/>
              <geom name="left_fr3_link5_collision" type="mesh" mesh="link5"/>
              <body name="left_fr3_link6" quat="0.707107 0.707107 0 0">
                <inertial pos="0.0597131 -0.0410295 -0.0101693" quat="0.621301 0.552665 0.510011 0.220081" mass="1.81704" diaginertia="0.0175039 0.0161123 0.00193529"/>
                <joint name="left_fr3_joint6" pos="0 0 0" axis="0 0 1" range="0.5445 4.5169" actuatorfrcrange="-12 12" damping="0.003" frictionloss="0.2"/>
                <geom name="left_fr3_link6_collision" type="mesh" mesh="link6"/>
                <body name="left_fr3_link7" pos="0.088 0 0" quat="0.707107 0.707107 0 0">
                  <inertial pos="0.00452258 0.00862619 -0.0161633" quat="0.727579 0.0978688 -0.24906 0.63168" mass="0.627143" diaginertia="0.000223836 0.000223642 5.64132e-07"/>
                  <joint name="left_fr3_joint7" pos="0 0 0" axis="0 0 1" range="-3.0159 3.0159" actuatorfrcrange="-12 12" damping="0.003" frictionloss="0.2"/>
                  <geom name="left_fr3_link7_collision" type="mesh" mesh="link7"/>
                </body>
              </body>
            </body>
          </body>
        </body>
      </body>
    </body>
    <body name="right_fr3_link1" pos="0.330538 -0.298991 0.855555" quat="0.865807 0.436878 0.0222879 0.242939">
      <inertial pos="4.128e-07 -0.0181251 -0.0386036" quat="0.998098 -0.0605364 0.00380499 0.0110109" mass="2.92747" diaginertia="0.0239286 0.0227246 0.00610634"/>
      <joint name="right_fr3_joint1" pos="0 0 0" axis="0 0 1" range="-2.7437 2.7437" actuatorfrcrange="-87 87" damping="0.003" frictionloss="0.2"/>
      <geom name="right_fr3_link1_collision" type="mesh" mesh="link1"/>
      <body name="right_fr3_link2" quat="0.707107 -0.707107 0 0">
        <inertial pos="0.00318289 -0.0743222 0.00881461" quat="0.502599 0.584437 -0.465998 0.434366" mass="2.93554" diaginertia="0.0629567 0.0411924 0.0246371"/>
        <joint name="right_fr3_joint2" pos="0 0 0" axis="0 0 1" range="-1.7837 1.7837" actuatorfrcrange="-87 87" damping="0.003" frictionloss="0.2"/>
        <geom name="right_fr3_link2_collision" type="mesh" mesh="link2"/>
        <body name="right_fr3_link3" pos="0 -0.316 0" quat="0.707107 0.707107 0 0">
          <inertial pos="0.0407016 -0.00482006 -0.0289731" quat="0.921025 -0.244161 0.155272 0.260745" mass="2.2449" diaginertia="0.0267409 0.0189869 0.0171587"/>
          <joint name="right_fr3_joint3" pos="0 0 0" axis="0 0 1" range="-2.9007 2.9007" actuatorfrcrange="-87 87" damping="0.003" frictionloss="0.2"/>
          <geom name="right_fr3_link3_collision" type="mesh" mesh="link3"/>
          <body name="right_fr3_link4" pos="0.0825 0 0" quat="0.707107 0.707107 0 0">
            <inertial pos="-0.0459101 0.0630493 -0.00851879" quat="0.438018 0.803311 0.00937812 0.403414" mass="2.6156" diaginertia="0.05139 0.0372717 0.0160047"/>
            <joint name="right_fr3_joint4" pos="0 0 0" axis="0 0 1" range="-3.0421 -0.1518" actuatorfrcrange="-87 87" damping="0.003" frictionloss="0.2"/>
            <geom name="right_fr3_link4_collision" type="mesh" mesh="link4"/>
            <body name="right_fr3_link5" pos="-0.0825 0.384 0" quat="0.707107 -0.707107 0 0">
              <inertial pos="-0.00160396 0.0292536 -0.0972966" quat="0.919031 0.125604 0.0751531 -0.366003" mass="2.32712" diaginertia="0.0579335 0.0449144 0.0130634"/>
              <joint name="right_fr3_joint5" pos="0 0 0" axis="0 0 1" range="-2.8065 2.8065" actuatorfrcrange="-12 12" damping="0.003" frictionloss="0.2"/>
              <geom name="right_fr3_link5_collision" type="mesh" mesh="link5"/>
              <body name="right_fr3_link6" quat="0.707107 0.707107 0 0">
                <inertial pos="0.0597131 -0.0410295 -0.0101693" quat="0.621301 0.552665 0.510011 0.220081" mass="1.81704" diaginertia="0.0175039 0.0161123 0.00193529"/>
                <joint name="right_fr3_joint6" pos="0 0 0" axis="0 0 1" range="0.5445 4.5169" actuatorfrcrange="-12 12" damping="0.003" frictionloss="0.2"/>
                <geom name="right_fr3_link6_collision" type="mesh" mesh="link6"/>
                <body name="right_fr3_link7" pos="0.088 0 0" quat="0.707107 0.707107 0 0">
                  <inertial pos="0.00452258 0.00862619 -0.0161633" quat="0.727579 0.0978688 -0.24906 0.63168" mass="0.627143" diaginertia="0.000223836 0.000223642 5.64132e-07"/>
                  <joint name="right_fr3_joint7" pos="0 0 0" axis="0 0 1" range="-3.0159 3.0159" actuatorfrcrange="-12 12" damping="0.003" frictionloss="0.2"/>
                  <geom name="right_fr3_link7_collision" type="mesh" mesh="link7"/>
                </body>
              </body>
            </body>
          </body>
        </body>
      </body>
    </body>
    <body name="caster_front_left_fixed_link" pos="0.33 0.26 0.124">
      <inertial pos="0 0 0" quat="0 0.707107 0 0.707107" mass="0.5" diaginertia="0.000104167 6.70417e-05 3.7875e-05"/>
      <joint name="caster_front_left_steering_joint" pos="0 0 0" axis="0 0 1" actuatorfrcrange="-500 500" damping="0.003"/>
      <body name="caster_front_left_link" pos="-0.035 0 -0.074">
        <inertial pos="0 0 0" quat="0.5 0.5 -0.5 0.5" mass="0.5" diaginertia="0.000625 0.000338542 0.000338542"/>
        <joint name="caster_front_left_joint" pos="0 0 0" axis="0 1 0" actuatorfrcrange="-500 500" damping="0.003"/>
        <geom quat="0.5 0.5 0.5 0.5" type="mesh" rgba="0.3 0.3 0.3 1" mesh="caster"/>
      </body>
    </body>
    <body name="caster_front_right_fixed_link" pos="0.33 -0.26 0.124">
      <inertial pos="0 0 0" quat="0 0.707107 0 0.707107" mass="0.5" diaginertia="0.000104167 6.70417e-05 3.7875e-05"/>
      <joint name="caster_front_right_steering_joint" pos="0 0 0" axis="0 0 1" actuatorfrcrange="-500 500" damping="0.003"/>
      <body name="caster_front_right_link" pos="-0.035 0 -0.074">
        <inertial pos="0 0 0" quat="0.5 0.5 -0.5 0.5" mass="0.5" diaginertia="0.000625 0.000338542 0.000338542"/>
        <joint name="caster_front_right_joint" pos="0 0 0" axis="0 1 0" actuatorfrcrange="-500 500" damping="0.003"/>
        <geom quat="0.5 0.5 0.5 0.5" type="mesh" rgba="0.3 0.3 0.3 1" mesh="caster"/>
      </body>
    </body>
    <body name="bogie_left_link" pos="-0.18 0.25 0.075">
      <inertial pos="0 0 0" quat="0.707107 0 0 0.707107" mass="3" diaginertia="0.0257 0.0256563 0.00015625"/>
      <joint name="bogie_left_joint" pos="0 0 0" axis="0 1 0" range="-0.16 0.18" actuatorfrcrange="-500 500" damping="0.003"/>
      <body name="l_wheel_link" pos="0.18 0.015 0.045">
        <inertial pos="0 0 0" quat="0.5 0.5 -0.5 0.5" mass="1" diaginertia="0.0072 0.00413333 0.00413333"/>
        <joint name="l_wheel_joint" pos="0 0 0" axis="0 1 0" actuatorfrcrange="-25 25"/>
        <geom quat="0 1 0 0" type="mesh" rgba="0.3 0.3 0.3 1" mesh="wheel"/>
      </body>
      <body name="caster_rear_left_fixed_link" pos="-0.13 0.01 0.049">
        <inertial pos="0 0 0" quat="0 0.707107 0 0.707107" mass="0.5" diaginertia="0.000104167 6.70417e-05 3.7875e-05"/>
        <joint name="caster_rear_left_steering_joint" pos="0 0 0" axis="0 0 1" actuatorfrcrange="-500 500" damping="0.003"/>
        <body name="caster_rear_left_link" pos="-0.035 0 -0.074">
          <inertial pos="0 0 0" quat="0.5 0.5 -0.5 0.5" mass="0.5" diaginertia="0.000625 0.000338542 0.000338542"/>
          <joint name="caster_rear_left_joint" pos="0 0 0" axis="0 1 0" actuatorfrcrange="-500 500" damping="0.003"/>
          <geom quat="0.5 0.5 0.5 0.5" type="mesh" rgba="0.3 0.3 0.3 1" mesh="caster"/>
        </body>
      </body>
    </body>
    <body name="bogie_right_link" pos="-0.18 -0.25 0.075">
      <inertial pos="0 0 0" quat="0.707107 0 0 0.707107" mass="3" diaginertia="0.0257 0.0256563 0.00015625"/>
      <joint name="bogie_right_joint" pos="0 0 0" axis="0 1 0" range="-0.16 0.18" actuatorfrcrange="-500 500" damping="0.003"/>
      <body name="r_wheel_link" pos="0.18 -0.015 0.045">
        <inertial pos="0 0 0" quat="0.5 0.5 -0.5 0.5" mass="1" diaginertia="0.0072 0.00413333 0.00413333"/>
        <joint name="r_wheel_joint" pos="0 0 0" axis="0 1 0" actuatorfrcrange="-25 25"/>
        <geom type="mesh" rgba="0.3 0.3 0.3 1" mesh="wheel"/>
      </body>
      <body name="caster_rear_right_fixed_link" pos="-0.13 -0.01 0.049">
        <inertial pos="0 0 0" quat="0 0.707107 0 0.707107" mass="0.5" diaginertia="0.000104167 6.70417e-05 3.7875e-05"/>
        <joint name="caster_rear_right_steering_joint" pos="0 0 0" axis="0 0 1" actuatorfrcrange="-500 500" damping="0.003"/>
        <body name="caster_rear_right_link" pos="-0.035 0 -0.074">
          <inertial pos="0 0 0" quat="0.5 0.5 -0.5 0.5" mass="0.5" diaginertia="0.000625 0.000338542 0.000338542"/>
          <joint name="caster_rear_right_joint" pos="0 0 0" axis="0 1 0" actuatorfrcrange="-500 500" damping="0.003"/>
          <geom quat="0.5 0.5 0.5 0.5" type="mesh" rgba="0.3 0.3 0.3 1" mesh="caster"/>
        </body>
      </body>
    </body>
  </worldbody>
</mujoco>
